Workbook

Sheet Grid Image Tracker
A1: Row # | B1: Family | C1: Capacity (ml) | D1: Glass Color | E1: Applicator Types | F1: Thread Size | G1: Display Name | H1: Category | I1: Collection | J1: Convex Slug | K1: Convex ID | L1: Primary Grace SKU | M1: Primary Website SKU | N1: All Legacy SKUs | O1: Product URL | P1: Has Hero Image? | Q1: Hero Image URL | R1: Variant Count | S1: Price Min ($) | T1: Price Max ($) | U1: Prompt Status | V1: Generation Status | W1: QA Status | X1: Notes
A2: 1 | B2: Apothecary | C2: 15 | D2: Cobalt Blue | E2: Glass Stopper | F2: Ground | G2: 15 ml Cobalt Blue Apothecary Applicator Bottle | H2: Glass Bottle | I2: Apothecary | J2: apothecary-15ml-cobalt-blue-Ground-glassapplicator | K2: kh75zzjck76jpqraxft0vhs4pd83k811 | L2: GB-APT-BLU-15ML-BLU-T | M2: GB15ApthBlue | N2: GB15ApthBlue | O2: https://www.bestbottles.com/product/Apothecary-style-15-ml-blue-glass-bottle-blue-glass-stopper | P2: No | R2: 1 | S2: 2.9 | T2: 2.9
A3: 2 | B3: Apothecary | C3: 30 | D3: Clear | E3: Glass Stopper | F3: Ground | G3: 30 ml Clear Apothecary Applicator Bottle | H3: Glass Bottle | I3: Apothecary | J3: apothecary-30ml-clear-Ground-glassapplicator | K3: kh74mjg1k626msbrwhjcj1jxvd83kev5 | L3: GB-APT-CLR-30ML-T | M3: GB1ozApth | N3: GB1ozApth | O3: https://www.bestbottles.com/product/Apothecary-style-1-ounce-clear-glass-bottle-clear-glass-stopper | P3: No | R3: 1 | S3: 2.9 | T3: 2.9
A4: 3 | B4: Apothecary | C4: 30 | D4: Cobalt Blue | E4: Glass Stopper | F4: Ground | G4: 30 ml Cobalt Blue Apothecary Applicator Bottle | H4: Glass Bottle | I4: Apothecary | J4: apothecary-30ml-cobalt-blue-Ground-glassapplicator | K4: kh758q30dj5dbqa4cqsyhkhaz983k8ex | L4: GB-APT-BLU-30ML-BLU-T | M4: GB1ozApthBlue | N4: GB1ozApthBlue | O4: https://www.bestbottles.com/product/Apothecary-style-1-ounce-blue-glass-bottle-blue-glass-stopper | P4: No | R4: 1 | S4: 2.9 | T4: 2.9
A5: 4 | B5: Apothecary | C5: 30 | D5: Green | E5: Glass Stopper | F5: Ground | G5: 30 ml Green Apothecary Applicator Bottle | H5: Glass Bottle | I5: Apothecary | J5: apothecary-30ml-green-Ground-glassapplicator | K5: kh7eay6sf6g6vkbxkc032vgntd83k6z1 | L5: GB-APT-GRN-30ML-GRN-T | M5: GB1ozApthGreen | N5: GB1ozApthGreen | O5: https://www.bestbottles.com/product/Apothecary-style-1-ounce-green-glass-bottle-green-glass-stopper | P5: No | R5: 1 | S5: 2.9 | T5: 2.9
A6: 5 | B6: Apothecary | C6: 118 | D6: Clear | E6: Cap/Closure | F6: Ground | G6: 118 ml Clear Pear Bottle with Stopper | H6: Glass Bottle | I6: Apothecary | J6: pear-118ml-clear-Ground-stopper | K6: kh7884mkyxnwzvk52rf1nptq5583kjf0 | L6: GB-DEC-CLR-118ML | M6: GBPearClear4ozStpr | N6: GBPearClear4ozStpr | O6: https://www.bestbottles.com/product/Apothecary-style-Clear-glass-cylindrical-4oz-glass-stopper | P6: No | R6: 1 | S6: 4.5 | T6: 4.5
A7: 6 | B7: Bell | C7: 10 | D7: Clear | E7: Cap/Closure | F7: 13-415 | G7: 10 ml Clear Bell Bottle | H7: Glass Bottle | I7: Bell Collection | J7: bell-10ml-clear-13-415-capclosure | K7: kh74qjssw50h0jgjprr0f2zrwd83k8yb | L7: GB-BEL-CLR-10ML-SHT-SBLK | M7: GBBell10BlkShSht | N7: GBBell10BlkShSht | O7: https://www.bestbottles.com/product/bell-design-10-ml-glass-bottle-short-shiny-black-cap | P7: No | R7: 1 | S7: 0.6 | T7: 0.6
A8: 7 | B8: Bell | C8: 10 | D8: Clear | E8: Cap/Closure | F8: 13-415 | G8: 10.0 ml Clear Bell Bottle with Cap | H8: Glass Bottle | J8: bell-10ml-clear-13-415 | K8: kh74vwsapbjsyxwyywndpdssn983jfgw | L8: GB-BLL-CLR-10ML-MRL-BDOT | M8: GBBell10MtlRollBlkDot | N8: GBBell10MtlRollBlkDot, GBBell10RollBlkDot | O8: https://www.bestbottles.com/product/bell-design-10-ml-glass-bottle-metal-roller-ball-plug-black-shiny-cap-with-dots | P8: No | R8: 2 | S8: 0.74 | T8: 0.82
A9: 8 | B9: Bell | C9: 10 | D9: Clear | E9: Fine Mist Sprayer | F9: 13-415 | G9: 10 ml Clear Bell Fine Mist Spray Bottle | H9: Glass Bottle | I9: Bell | J9: bell-10ml-clear-13-415-finemist | K9: kh72622695yfgrq69fp0xx5rbs83je3g | L9: GB-BEL-CLR-10ML-SPR-SBLK | M9: GBBell10SpryBlkSh | N9: GBBell10SpryBlkSh | O9: https://www.bestbottles.com/product/bell-design-10-ml-clear-glass-bottle-shiny-black-spray | P9: No | R9: 1 | S9: 0.9 | T9: 0.9
A10: 9 | B10: Bell | C10: 10 | D10: Clear | E10: Metal Roller Ball, Plastic Roller Ball | F10: 13-415 | G10: 10 ml Clear Bell Roll-On Bottle | H10: Glass Bottle | I10: Bell Collection | J10: bell-10ml-clear-13-415-rollon | K10: kh7a5c349tvj8n8sa46w9de8jx83kxgs | L10: GB-BEL-CLR-10ML-ROL-BLDOT | M10: GBBell10RollBlkDot | N10: GBBell10RollBlkDot, GBBell10MtlRollBlkDot | O10: https://www.bestbottles.com/product/bell-design-10-ml-glass-bottle-plastic-roller-ball-plug-black-shiny-cap-with-dots | P10: No | R10: 2 | S10: 0.74 | T10: 0.82
A11: 10 | B11: Boston Round | C11: 15 | D11: Amber | E11: Cap/Closure | F11: 18-400 | G11: 15 ml Amber Boston Round Bottle with Cap | H11: Glass Bottle | I11: Boston Round | J11: boston-round-15ml-amber-18-400 | K11: kh7dyyag722vnby7v0vtk86y9183k1qm | L11: GB-BSR-AMB-15ML-BLK-S | M11: GBBstnAmb15mlBlkCapSht | N11: GBBstnAmb15mlBlkCapSht | O11: https://www.bestbottles.com/product/boston-round-design-15-ml-amber-glass-bottle-black-short-cap | P11: No | R11: 1 | S11: 0.42 | T11: 0.42
A12: 11 | B12: Boston Round | C12: 15 | D12: Amber | E12: Dropper | F12: 18-400 | G12: 15 ml Amber Boston Round Dropper Bottle | H12: Glass Bottle | I12: Boston Round | J12: boston-round-15ml-amber-18-400-dropper | K12: kh70zt06mq8ebwfe1rbrjzsban83jng8 | L12: GB-BSR-AMB-15ML-BLK-T-03 | M12: GBBstnAmb15mlBlkDropperSlTrim | N12: GBBstnAmb15mlBlkDropperSlTrim, GBBstnAmb15mlWhtDropper, GBBstnAmb15mlWhtDropperGlTrim, GBBstnAmb15mlWhtDropperSlTrim, GBBstnAmb15mlBlkDropperGlTrim | O12: https://www.bestbottles.com/product/boston-round-design-15-ml-amber-glass-bottle-black-dropper-shiny-silver-trim-cap | P12: No | R12: 6 | S12: 0.67 | T12: 0.82
A13: 12 | B13: Boston Round | C13: 15 | D13: Clear | E13: Cap/Closure | F13: 18-400 | G13: 15 ml Clear Boston Round Bottle with Cap | H13: Glass Bottle | I13: Boston Round | J13: boston-round-15ml-clear-18-400 | K13: kh782gspzag63xwn768bt9j98x83jc0d | L13: GB-BSR-CLR-15ML-BLK-S | M13: GBBstn15BlkCapSht | N13: GBBstn15BlkCapSht | O13: https://www.bestbottles.com/product/boston-round-design-15-ml-clear-glass-bottle-black-short-cap | P13: No | R13: 2 | S13: 0.42 | T13: 0.67
A14: 13 | B14: Boston Round | C14: 15 | D14: Cobalt Blue | E14: Cap/Closure | F14: 18-400 | G14: 15 ml Cobalt Blue Boston Round Bottle with Cap | H14: Glass Bottle | I14: Boston Round | J14: boston-round-15ml-cobalt-blue-18-400 | K14: kh765ptesrzsaz6s354zagtxxh83kp4e | L14: GB-BSR-CBL-15ML-BLK-S | M14: GBBstnBlu15BlkCapSht | N14: GBBstnBlu15BlkCapSht | O14: https://www.bestbottles.com/product/boston-round-design-15-ml-cobalt-blue-glass-bottle-black-short-cap | P14: No | R14: 1 | S14: 0.42 | T14: 0.42
A15: 14 | B15: Boston Round | C15: 15 | D15: Cobalt Blue | E15: Dropper | F15: 18-400 | G15: 15 ml Cobalt Blue Boston Round Dropper Bottle | H15: Glass Bottle | I15: Boston Round | J15: boston-round-15ml-cobalt-blue-18-400-dropper | K15: kh79y1hddtdfwsmy4afhvs5n7h83j0gm | L15: GB-BSR-CBL-15ML-WHT-T-01 | M15: GBBstnBlu15WhtDrpr | N15: GBBstnBlu15WhtDrpr, GBBstnBlu15WhtDrprSlTrim, GBBstnBlu15WhtDrprGlTrim, GBBstnBlu15mlBlkDropperSlTrim, GBBstnBlu15BlkDrprGlTrim | O15: https://www.bestbottles.com/product/boston-round-design-15-ml-cobalt-blue-glass-bottle-white-dropper | P15: No | R15: 6 | S15: 0.67 | T15: 0.82
A16: 15 | B16: Boston Round | C16: 30 | D16: Amber | E16: Cap/Closure | F16: 20-400 | G16: 30 ml Amber Boston Round Bottle with Cap | H16: Glass Bottle | I16: Boston Round | J16: boston-round-30ml-amber-20-400 | K16: kh7170jj2eaz3s2g6qa5t17y2d83k8hp | L16: GB-BSR-AMB-30ML-BLK-S | M16: GBBstnAmb1ozBlkCapSht | N16: GBBstnAmb1ozBlkCapSht | O16: https://www.bestbottles.com/product/boston-round-design-1-oz-amber-glass-bottle-short-black-cap | P16: No | R16: 1 | S16: 0.47 | T16: 0.47
A17: 16 | B17: Boston Round | C17: 30 | D17: Amber | E17: Dropper | F17: 20-400 | G17: 30 ml Amber Boston Round Dropper Bottle | H17: Glass Bottle | I17: Boston Round | J17: boston-round-30ml-amber-20-400-dropper | K17: kh78qzqrp4sa5z7gtavefg985183ksc5 | L17: GB-BSR-AMB-30ML-BLK-T-02 | M17: GBBstnAmb1ozBlkDrpShnGl | N17: GBBstnAmb1ozBlkDrpShnGl, GBBstnAmb1ozWhtDropper, GBBstnAmb1ozWhtDropperShnGlTrim, GBBstnAmb1ozWhtDrprShnSlTrim | O17: https://www.bestbottles.com/product/boston-round-design-1-oz-amber-glass-bottle-black-dropper-shiny-silver-trim-cap | P17: No | R17: 5 | S17: 0.72 | T17: 0.87
A18: 17 | B18: Boston Round | C18: 30 | D18: Amber | E18: Metal Roller Ball, Plastic Roller Ball | F18: 20-400 | G18: 30 ml Amber Boston Round Roll-On Bottle | H18: Glass Bottle | I18: Boston Round | J18: boston-round-30ml-amber-20-400-rollon | K18: kh7czj3k0nw98n0ecvtz7pa07h83k4vt | L18: GB-BSR-AMB-30ML-MRL-MBLK | M18: GBBstnAmb1ozMtlRollonMattBlk | N18: GBBstnAmb1ozMtlRollonMattBlk, GBBstnAmb1ozMtlRollonMattGl, GBBstnAmb1ozMtlRollonMattSl, GBBstnAmb1ozMtlRollonShnSl, GBBstnAmb1ozMtlRollonShnBlk, GBBstnAmb1ozRollonMattGl, GBBstnAmb1ozRollonMattBlk, GBBstnAmb1ozRollonMattSl, GBBstnAmb1ozRollonShnSl, GBBstnAmb1ozRollonShnBlk | O18: https://www.bestbottles.com/product/boston-round-design-1-oz-amber-glass-bottle-metal-roller-ball-matte-black-cap | P18: No | R18: 12 | S18: 0.92 | T18: 1.07
A19: 18 | B19: Boston Round | C19: 30 | D19: Clear | E19: Cap/Closure | F19: 20-400 | G19: 30 ml Clear Boston Round Bottle with Cap | H19: Glass Bottle | I19: Boston Round | J19: boston-round-30ml-clear-20-400 | K19: kh7cq9kpdyrwqw8cnevh33743h83jgdt | L19: GB-BSR-CLR-30ML-BLK-S | M19: GBBstn1ozBlkCapSht | N19: GBBstn1ozBlkCapSht | O19: https://www.bestbottles.com/product/boston-round-design-1-oz-clear-glass-bottle-short-black-cap | P19: No | R19: 1 | S19: 0.47 | T19: 0.47
A20: 19 | B20: Boston Round | C20: 30 | D20: Clear | E20: Dropper | F20: 20-400 | G20: 30 ml Clear Boston Round Dropper Bottle | H20: Glass Bottle | I20: Boston Round | J20: boston-round-30ml-clear-20-400-dropper | K20: kh7c6gancdwmyvdh02zzgnqmgh83k6ja | L20: GB-BSR-CLR-30ML-DRP-WHT-T | M20: GBBstn1ozWhtDrp | N20: GBBstn1ozWhtDrp, GBBstn1ozBlkDrpShnGlTrim, GBBstn1ozWhtDrpShnGlTrim, GBBstn1ozWhtDrpShnSlTrim | O20: https://www.bestbottles.com/product/boston-round-design-1-oz-clear-glass-bottle-white-dropper | P20: No | R20: 5 | S20: 0.72 | T20: 0.87
... A24: 23 | B24: Boston Round | C24: 30 | D24: Cobalt Blue | E24: Metal Roller Ball, Plastic Roller Ball | F24: 20-400 | G24: 30 ml Cobalt Blue Boston Round Roll-On Bottle | H24: Glass Bottle | I24: Boston Round | J24: boston-round-30ml-cobalt-blue-20-400-rollon | K24: kh7bah1myb7ep7p6a3waj8vxyx83kdrp | L24: GB-BSR-BLU-30ML-MRO-MSLV | M24: GBBstnBlu1ozMtlRollonMattSl | N24: GBBstnBlu1ozMtlRollonMattSl, GBBstnBlu1ozMtlRollonShnSl, GBBstnBlu1ozMtlRollonMattBlk, GBBstnBlu1ozMtlRollonMattGl, GBBstnBlu1ozRollonMattBlk, GBBstnBlu1ozRollonMattSl, GBBstnBlu1ozRollonShnSl, GBBstnBlu1ozRollonMattGl, GBBstnBlu1ozRollonShnBlk | O24: https://www.bestbottles.com/product/boston-round-design-1-oz-cobalt-blue-glass-bottle-metal-roller-ball-matte-silver-cap | P24: No | R24: 11 | S24: 0.92 | T24: 1.07
A25: 24 | B25: Boston Round | C25: 60 | D25: Amber | E25: Cap/Closure | F25: 20-400 | G25: 60 ml Amber Boston Round Bottle with Cap | H25: Glass Bottle | I25: Boston Round | J25: boston-round-60ml-amber-20-400 | K25: kh73nbkb4nqvvd7ffmffqq75pd83kh73 | P25: No | R25: 1 | S25: 0.5 | T25: 0.5
A26: 25 | B26: Boston Round | C26: 60 | D26: Amber | E26: Dropper | F26: 20-400 | G26: 60 ml Amber Boston Round Dropper Bottle | H26: Glass Bottle | I26: Boston Round | J26: boston-round-60ml-amber-20-400-dropper | K26: kh76pa5emzxqqfze0hhbnqya1n83jn5v | L26: GB-BSR-AMB-60ML-BLK-T-01 | M26: GBBstnAmb2ozBlkDropperShnGlTrim | N26: GBBstnAmb2ozBlkDropperShnGlTrim, GBBstnAmb2ozBlkDrprShnSlTrim, GBBstnAmb2ozWhtDrpr, GBBstnAmb2ozWhtDropperShnGlTrim, GBBstnAmb2ozWhtDropperShnSlTrim | O26: https://www.bestbottles.com/product/boston-round-2-oz-amber-glass-bottle-black-dropper-shiny-gold-trim-cap | P26: No | R26: 6 | S26: 0.75 | T26: 0.9
A27: 26 | B27: Boston Round | C27: 60 | D27: Amber | E27: Metal Roller Ball, Plastic Roller Ball | F27: 20-400 | G27: 60 ml Amber Boston Round Roll-On Bottle | H27: Glass Bottle | I27: Boston Round | J27: boston-round-60ml-amber-20-400-rollon | K27: kh71fh484peh58j1vkkwawrma983kvjf | L27: GB-BSR-AMB-60ML-MRL-MBLK | M27: GBBstnAmb2ozMtlRollonMattBlk | N27: GBBstnAmb2ozMtlRollonMattBlk, GBBstnAmb2ozMtlRollonMattGl, GBBstnAmb2ozMtlRollonMattSl, GBBstnAmb2ozMtlRollonShnSl, GBBstnAmb2ozRollonMattGl, GBBstnAmb2ozRollonMattBlk, GBBstnAmb2ozRollonMattSl, GBBstnAmb2ozRollonShnSl, GBBstnAmb2ozRollonShnBlk | O27: https://www.bestbottles.com/product/boston-round-2-oz-amber-glass-bottle-metal-roller-ball-matte-black-cap | P27: No | R27: 11 | S27: 0.95 | T27: 1.1
A28: 27 | B28: Boston Round | C28: 60 | D28: Clear | E28: Cap/Closure | F28: 20-400 | G28: 60 ml Clear Boston Round Bottle with Cap | H28: Glass Bottle | I28: Boston Round | J28: boston-round-60ml-clear-20-400 | K28: kh7et2z1x51nbad88r7dq7g34x83j59f | L28: GB-BSR-CLR-60ML-BLK-S | M28: GBBstn2ozBlkCapSht | N28: GBBstn2ozBlkCapSht | O28: https://www.bestbottles.com/product/boston-round-2-oz-clear-glass-bottle-short-black-cap | P28: No | R28: 1 | S28: 0.5 | T28: 0.5
A29: 28 | B29: Boston Round | C29: 60 | D29: Clear | E29: Dropper | F29: 20-400 | G29: 60 ml Clear Boston Round Dropper Bottle | H29: Glass Bottle | I29: Boston Round | J29: boston-round-60ml-clear-20-400-dropper | K29: kh749ym1nb1fw06d1cfdv2c9nn83jbqw | L29: GB-BSR-CLR-60ML-WHT-T-01 | M29: GBBstn2ozWhtDrpr | N29: GBBstn2ozWhtDrpr, GBBstn2ozBlkDrprShnGlTrim, GBBstn2ozWhtDrprShnSlTrim, GBBstn2ozBlkDrprShnSlTrim, GBBstn2ozWhtDrprShnGlTrim | O29: https://www.bestbottles.com/product/boston-round-2-oz-clear-glass-bottle-white-dropper | P29: No | R29: 6 | S29: 0.75 | T29: 0.9
A30: 29 | B30: Boston Round | C30: 60 | D30: Clear | E30: Metal Roller Ball, Plastic Roller Ball | F30: 20-400 | G30: 60 ml Clear Boston Round Roll-On Bottle | H30: Glass Bottle | I30: Boston Round | J30: boston-round-60ml-clear-20-400-rollon | K30: kh7er149qmh3htzhyqsc62aajx83jwxb | L30: GB-BSR-CLR-60ML-MRL-SGLD | M30: GBBstn2ozMtlRollGl | N30: GBBstn2ozMtlRollGl, GBBstn2ozMtlRollMattBlk, GBBstn2ozMtlRollMattGl, GBBstn2ozMtlRollMattSl, GBBstn2ozMtlRollShnSl, GBBstn2ozRollShnBlk, GBBstn2ozRollonMattGl, GBBstn2ozRollMattBlk, GBBstn2ozRollMattSl, GBBstn2ozRollShnSl | O30: https://www.bestbottles.com/product/boston-round-2-oz-clear-glass-bottle-metal-roller-ball-shiny-gold-cap | P30: No | R30: 12 | S30: 0.95 | T30: 1.1
A31: 30 | B31: Boston Round | C31: 60 | D31: Cobalt Blue | E31: Cap/Closure | F31: 20-400 | G31: 60 ml Cobalt Blue Boston Round Bottle with Cap | H31: Glass Bottle | I31: Boston Round | J31: boston-round-60ml-cobalt-blue-20-400 | K31: kh78ktkha8ezsg055nsty1c2yh83jm8y | P31: No | R31: 1 | S31: 0.5 | T31: 0.5
A32: 31 | B32: Boston Round | C32: 60 | D32: Cobalt Blue | E32: Dropper | F32: 20-400 | G32: 60 ml Cobalt Blue Boston Round Dropper Bottle | H32: Glass Bottle | I32: Boston Round | J32: boston-round-60ml-cobalt-blue-20-400-dropper | K32: kh79fy1y6vgbzfy81n3ym4d5d183ky22 | L32: GB-BSR-CBL-60ML-BLK-T-02 | M32: GBBstnBlu2ozBlkDropperShnGlTrim | N32: GBBstnBlu2ozBlkDropperShnGlTrim, GBBstnBlu2ozWhtDropper, GBBstnBlu2ozWhtDropperShnGlTrim, GBBstnBlu2ozWhtDropperShnSlTrim | O32: https://www.bestbottles.com/product/boston-round-2-oz-cobalt-blue-glass-bottle-black-dropper-shiny-silver-trim-cap | P32: No | R32: 5 | S32: 0.75 | T32: 0.9
A33: 32 | B33: Boston Round | C33: 60 | D33: Cobalt Blue | E33: Metal Roller Ball, Plastic Roller Ball | F33: 20-400 | G33: 60 ml Cobalt Blue Boston Round Roll-On Bottle | H33: Glass Bottle | I33: Boston Round | J33: boston-round-60ml-cobalt-blue-20-400-rollon | K33: kh77xagzregbgtaj03zsj6p8as83jr05 | L33: GB-BSR-BLU-60ML-MRO-MBLK | M33: GBBstnBlu2ozMtlRollonMattBlk | N33: GBBstnBlu2ozMtlRollonMattBlk, GBBstnBlu2ozMtlRollonMattGl, GBBstnBlu2ozMtlRollonMattSl, GBBstnBlu2ozMtlRollonShnSl, GBBstnBlu2ozRollonMattGl, GBBstnBlu2ozRollonMattBlk, GBBstnBlu2ozRollonMattSl, GBBstnBlu2ozRollonShnSl, GBBstnBlu2ozRollonShnBlk | O33: https://www.bestbottles.com/product/boston-round-2-oz-cobalt-blue-glass-bottle-metal-roller-ball-matte-black-cap | P33: No | R33: 11 | S33: 0.95 | T33: 1.1
A34: 33 | B34: Circle | C34: 15 | D34: Clear | E34: Cap/Closure | F34: 13-415 | G34: 15 ml Clear Circle Bottle with Cap | H34: Glass Bottle | I34: Circle | J34: circle-15ml-clear-13-415 | K34: kh79714cytrh3ycr5jdx5ca9yn83kssb | L34: GB-CIR-CLR-15ML-GLD-T | M34: GBCrcl15Gl | N34: GBCrcl15Gl, GBCrcl15Sl, GBCrcl15WhtSht, GBCrcl15BlkSht | O34: https://www.bestbottles.com/product/circle-design-15-ml-bottle-shiny-gold-cap | P34: No | R34: 4 | S34: 0.44 | T34: 0.62
A35: 34 | B35: Circle | C35: 15 | D35: Clear | E35: Fine Mist Sprayer | F35: 13-415 | G35: 15 ml Clear Circle Fine Mist Spray Bottle | H35: Glass Bottle | I35: Circle | J35: circle-15ml-clear-13-415-finemist | K35: kh7f52btez6qp6mvrk0x52vgnd83kp84 | L35: GB-CIR-CLR-15ML-SPR-MBLK | M35: GBCrcl15SpryBlkMatt | N35: GBCrcl15SpryBlkMatt | O35: https://www.bestbottles.com/product/circle-design-15-ml-bottle-matte-black-spray | P35: No | R35: 8 | S35: 0.97 | T35: 0.97
A36: 35 | B36: Circle | C36: 15 | D36: Clear | E36: Plastic Roller Ball | F36: 13-415 | G36: 15 ml Clear Circle Roll-On Bottle | H36: Glass Bottle | I36: Circle | J36: circle-15ml-clear-13-415-rollon | K36: kh7714036h7avy03vwfhfdz27x83k3aj | L36: GB-CIR-CLR-15ML-ROL-SBLK | M36: GBCrcl15RollBlkSh | N36: GBCrcl15RollBlkSh, GBCrcl15RollCuMatt, GBCrcl15RollGlMatt, GBCrcl15RollGlSh, GBCrcl15RollPinkDot, GBCrcl15RollSlDot, GBCrcl15RollSlMatt, GBCrcl15RollSlSh, GBCrcl15RollBlkDot | O36: https://www.bestbottles.com/product/circle-design-15-ml-bottle-plastic-roller-ball-plug-black-shiny-cap | P36: No | R36: 18 | S36: 0.74 | T36: 0.89
A37: 36 | B37: Circle | C37: 30 | D37: Clear | E37: Cap/Closure | F37: 15-415 | G37: 30 ml Clear Circle Bottle with Cap | H37: Glass Bottle | I37: Circle | J37: circle-30ml-clear-15-415 | K37: kh79ct48bayjn5660asde3h0cn83kcpe | L37: GB-CIR-CLR-30ML-GLD-T | M37: GBCrcl30GlCap | N37: GBCrcl30GlCap, GBCrcl30SlCap | O37: https://www.bestbottles.com/product/circle-design-30-ml-clear-glass-bottle-shiny-gold-cap | P37: No | R37: 2 | S37: 1.4 | T37: 1.4
A38: 37 | B38: Circle | C38: 30 | D38: Clear | E38: Perfume Spray Pump | F38: 15-415 | G38: 30 ml Clear Circle Bottle | H38: Glass Bottle | I38: Circle | J38: circle-30ml-clear-15-415-perfumespray | K38: kh79jg7f379p1htf0f50eha17n83jd0k | L38: GB-CIR-BLK-30ML-SPR-BLK | M38: GBCrcl30SpryBlk | N38: GBCrcl30SpryBlk | O38: https://www.bestbottles.com/product/circle-design-30-ml-clear-glass-bottle-sprayer-black-cap | P38: No | R38: 5 | S38: 2.25 | T38: 2.25
A39: 38 | B39: Circle | C39: 50 | D39: Clear | E39: Dropper | F39: 18-415 | G39: 50 ml Clear Circle Dropper Bottle | H39: Glass Bottle | I39: Circle | J39: circle-50ml-clear-18-415-dropper | K39: kh78db9xnh6bxrcqdwqhphrrqn83ksp4 | L39: GB-CIR-CLR-50ML-DRP-SLV | M39: GBCrcl50DrpSl | N39: GBCrcl50DrpSl, GBCrcl50DrpGl | O39: https://www.bestbottles.com/product/circle-design-50-ml-glass-bottle-white-dropper-shiny-silver-collar-cap | P39: No | R39: 3 | S39: 1.75 | T39: 1.75
A40: 39 | B40: Circle | C40: 50 | D40: Clear | E40: Lotion Pump | F40: 18-415 | G40: 50 ml Clear Circle Lotion Pump Bottle | H40: Glass Bottle | I40: Circle | J40: circle-50ml-clear-18-415-lotionpump | K40: kh72hg7gastpgkf0vvydef5d6d83jy3a | P40: No | R40: 7 | S40: 2.6 | T40: 2.6
A41: 40 | B41: Circle | C41: 50 | D41: Clear | E41: Perfume Spray Pump | F41: 18-415 | G41: 50 ml Clear Circle Bottle | H41: Glass Bottle | I41: Circle | J41: circle-50ml-clear-18-415-perfumespray | K41: kh7ewg149nvqray49hew2agw7583kqar | L41: GB-CIR-CLR-50ML-SPR-MSLV | M41: GBCrcl50SpryMtSl | N41: GBCrcl50SpryMtSl, GBCrcl50SpryMtGl, GBCrcl50SpryShnGl, GBCrcl50SpryShnBlk, GBCrcl50SpryShnSl, GBCrcl50SpryCu | O41: https://www.bestbottles.com/product/circle-design-50-ml-glass-bottle-matte-silver-spray-pump-and-cap | P41: No | R41: 6 | S41: 2.6 | T41: 2.6
A42: 41 | B42: Circle | C42: 50 | D42: Clear | E42: Reducer | F42: 18-415 | G42: 50 ml Clear Circle Reducer Bottle | H42: Glass Bottle | I42: Circle | J42: circle-50ml-clear-18-415-reducer | K42: kh73rpr9my9dy8n9jdjrq1bbyn83jqm0 | L42: GB-CIR-CLR-50ML-RDC-BKLT | M42: GBCrcl50RdcrBlkLthr | N42: GBCrcl50RdcrBlkLthr | O42: https://www.bestbottles.com/product/circle-design-50-ml-glass-bottle-reducer-black-faux-leather-cap | P42: No | R42: 12 | S42: 1.57 | T42: 1.85
A43: 42 | B43: Circle | C43: 50 | D43: Clear | E43: Vintage Bulb Sprayer | F43: 18-415 | G43: 50 ml Clear Circle Vintage Bulb Spray Bottle | H43: Glass Bottle | I43: Circle | J43: circle-50ml-clear-18-415-antiquespray | K43: kh7e58z20zqh04nzyeg5vqgn1h83k856 | L43: GB-CIR-CLR-50ML-ASP-BLK | M43: GBCrcl50AnSpBlk | N43: GBCrcl50AnSpBlk | O43: https://www.bestbottles.com/product/circle-design-50-ml-glass-bottle-black-vintage-style-bulb-sprayer-shiny-silver-collar-cap | P43: No | R43: 11 | S43: 5.45 | T43: 6.2
...

Sheet Dashboard
B1: Grid Image Tracker — Dashboard
B2: Generated: 2026-04-06 | Live Convex + frontend-aligned applicator types
B4: Summary Statistics
B5: Total Glass Bottle Groups | C5: =COUNTA('Grid Image Tracker'!B2:B292)
B6: Groups with Hero Image | C6: =COUNTIF('Grid Image Tracker'!P2:P292,"Yes")
B7: Groups without Hero Image | C7: =COUNTIF('Grid Image Tracker'!P2:P292,"No")
B8: % Complete (Hero Images) | C8: =IF(C6>0,C6/C5,"")
B9: Groups with Product URL | C9: =COUNTA('Grid Image Tracker'!O2:O292)
B10: Groups with Legacy SKUs | C10: =COUNTA('Grid Image Tracker'!N2:N292)
B11: Total Product Variants | C11: =SUM('Grid Image Tracker'!R2:R292)
B13: Generation Pipeline
B14: Prompts Written | C14: =COUNTA('Grid Image Tracker'!U2:U292)
B15: Images Generated | C15: =COUNTA('Grid Image Tracker'!V2:V292)
B16: QA Passed | C16: =COUNTIF('Grid Image Tracker'!W2:W292,"Pass")
B17: QA Failed | C17: =COUNTIF('Grid Image Tracker'!W2:W292,"Fail")
B19: By Applicator Type
B20: Applicator Type | C20: Total | D20: Has Hero | E20: Needs Image
B21: Metal Roller Ball | C21: =COUNTIF('Grid Image Tracker'!E2:E292,"*Metal Roller Ball*") | D21: =COUNTIFS('Grid Image Tracker'!E2:E292,"*Metal Roller Ball*",'Grid Image Tracker'!P2:P292,"Yes") | E21: =C21-D21
B22: Plastic Roller Ball | C22: =COUNTIF('Grid Image Tracker'!E2:E292,"*Plastic Roller Ball*") | D22: =COUNTIFS('Grid Image Tracker'!E2:E292,"*Plastic Roller Ball*",'Grid Image Tracker'!P2:P292,"Yes") | E22: =C22-D22
B23: Fine Mist Sprayer | C23: =COUNTIF('Grid Image Tracker'!E2:E292,"*Fine Mist Sprayer*") | D23: =COUNTIFS('Grid Image Tracker'!E2:E292,"*Fine Mist Sprayer*",'Grid Image Tracker'!P2:P292,"Yes") | E23: =C23-D23
B24: Perfume Spray Pump | C24: =COUNTIF('Grid Image Tracker'!E2:E292,"*Perfume Spray Pump*") | D24: =COUNTIFS('Grid Image Tracker'!E2:E292,"*Perfume Spray Pump*",'Grid Image Tracker'!P2:P292,"Yes") | E24: =C24-D24
B25: Reducer | C25: =COUNTIF('Grid Image Tracker'!E2:E292,"*Reducer*") | D25: =COUNTIFS('Grid Image Tracker'!E2:E292,"*Reducer*",'Grid Image Tracker'!P2:P292,"Yes") | E25: =C25-D25
B26: Dropper | C26: =COUNTIF('Grid Image Tracker'!E2:E292,"*Dropper*") | D26: =COUNTIFS('Grid Image Tracker'!E2:E292,"*Dropper*",'Grid Image Tracker'!P2:P292,"Yes") | E26: =C26-D26
B27: Lotion Pump | C27: =COUNTIF('Grid Image Tracker'!E2:E292,"*Lotion Pump*") | D27: =COUNTIFS('Grid Image Tracker'!E2:E292,"*Lotion Pump*",'Grid Image Tracker'!P2:P292,"Yes") | E27: =C27-D27
B28: Vintage Bulb Sprayer | C28: =COUNTIF('Grid Image Tracker'!E2:E292,"*Vintage Bulb Sprayer*") | D28: =COUNTIFS('Grid Image Tracker'!E2:E292,"*Vintage Bulb Sprayer*",'Grid Image Tracker'!P2:P292,"Yes") | E28: =C28-D28
B29: Vintage Bulb Sprayer with Tassel | C29: =COUNTIF('Grid Image Tracker'!E2:E292,"*Vintage Bulb Sprayer with Tassel*") | D29: =COUNTIFS('Grid Image Tracker'!E2:E292,"*Vintage Bulb Sprayer with Tassel*",'Grid Image Tracker'!P2:P292,"Yes") | E29: =C29-D29
B30: Atomizer | C30: =COUNTIF('Grid Image Tracker'!E2:E292,"*Atomizer*") | D30: =COUNTIFS('Grid Image Tracker'!E2:E292,"*Atomizer*",'Grid Image Tracker'!P2:P292,"Yes") | E30: =C30-D30
B31: Glass Stopper | C31: =COUNTIF('Grid Image Tracker'!E2:E292,"*Glass Stopper*") | D31: =COUNTIFS('Grid Image Tracker'!E2:E292,"*Glass Stopper*",'Grid Image Tracker'!P2:P292,"Yes") | E31: =C31-D31
B32: Glass Rod | C32: =COUNTIF('Grid Image Tracker'!E2:E292,"*Glass Rod*") | D32: =COUNTIFS('Grid Image Tracker'!E2:E292,"*Glass Rod*",'Grid Image Tracker'!P2:P292,"Yes") | E32: =C32-D32
B33: Cap/Closure | C33: =COUNTIF('Grid Image Tracker'!E2:E292,"*Cap/Closure*") | D33: =COUNTIFS('Grid Image Tracker'!E2:E292,"*Cap/Closure*",'Grid Image Tracker'!P2:P292,"Yes") | E33: =C33-D33
B35: By Family
B36: Family | C36: Total | D36: Has Hero | E36: Needs Image
B37: Apothecary | C37: =COUNTIF('Grid Image Tracker'!B2:B292,"Apothecary") | D37: =COUNTIFS('Grid Image Tracker'!B2:B292,"Apothecary",'Grid Image Tracker'!P2:P292,"Yes") | E37: =C37-D37
B38: Bell | C38: =COUNTIF('Grid Image Tracker'!B2:B292,"Bell") | D38: =COUNTIFS('Grid Image Tracker'!B2:B292,"Bell",'Grid Image Tracker'!P2:P292,"Yes") | E38: =C38-D38
B39: Boston Round | C39: =COUNTIF('Grid Image Tracker'!B2:B292,"Boston Round") | D39: =COUNTIFS('Grid Image Tracker'!B2:B292,"Boston Round",'Grid Image Tracker'!P2:P292,"Yes") | E39: =C39-D39
B40: Circle | C40: =COUNTIF('Grid Image Tracker'!B2:B292,"Circle") | D40: =COUNTIFS('Grid Image Tracker'!B2:B292,"Circle",'Grid Image Tracker'!P2:P292,"Yes") | E40: =C40-D40
B41: Cylinder | C41: =COUNTIF('Grid Image Tracker'!B2:B292,"Cylinder") | D41: =COUNTIFS('Grid Image Tracker'!B2:B292,"Cylinder",'Grid Image Tracker'!P2:P292,"Yes") | E41: =C41-D41
B42: Decorative | C42: =COUNTIF('Grid Image Tracker'!B2:B292,"Decorative") | D42: =COUNTIFS('Grid Image Tracker'!B2:B292,"Decorative",'Grid Image Tracker'!P2:P292,"Yes") | E42: =C42-D42
B43: Diamond | C43: =COUNTIF('Grid Image Tracker'!B2:B292,"Diamond") | D43: =COUNTIFS('Grid Image Tracker'!B2:B292,"Diamond",'Grid Image Tracker'!P2:P292,"Yes") | E43: =C43-D43
B44: Diva | C44: =COUNTIF('Grid Image Tracker'!B2:B292,"Diva") | D44: =COUNTIFS('Grid Image Tracker'!B2:B292,"Diva",'Grid Image Tracker'!P2:P292,"Yes") | E44: =C44-D44
...

Sheet Prompt Log
A1: # | B1: Family | C1: Capacity (ml) | D1: Glass Color | E1: Applicator Type | F1: Prompt Text | G1: Gen Tool | H1: Thinking Level | I1: Attempts | J1: Best Result URL | K1: Notes
A2: 1 | B2: Cylinder | C2: 5 | D2: Clear | E2: Fine Mist Sprayer | F2: Professional e-commerce product photograph of a tall, slender clear glass 5ml cylinder fine mist spray bottle shown WITHOUT its overcap. The overcap is placed standing upright beside the bottle on the right side, revealing the spray mechanism. EXACT BOTTLE SHAPE: Tall, slender cylinder spray bottle. The glass body height-to-width ratio is approximately 3.2:1. The body is a perfect cylinder with absolutely straight parallel sides — no taper, no bulge, no curves, no waist. Flat bottom sits flush on the stone surface. The spray mechanism extends above the glass body, adding about 22% to the total height. With the sprayer exposed (no overcap), the total height-to-body-width ratio is approximately 4.2:1. The bottle is EMPTY — no liquid inside. SPRAY MECHANISM — critical detail: The fine mist spray pump is FULLY COLORED — the entire mechanism is a single solid matte black finish. This is NOT a white sprayer with a colored band — the actuator button, the collar, the tube housing are ALL matte black. The spray nozzle points upward. The mechanism sits flush with the glass body diameter. A thin dip tube extends down inside the bottle (barely visible through the clear glass). GLASS / MATERIAL: Crystal clear transparent glass with subtle refractive quality. Perfectly transparent. Thin dark outlines visible at glass edges where light refracts through cylindrical walls. No cloudiness, no bubbles, no imperfections. Premium optical clarity. EMPTY — no liquid fill. OVERCAP PLACEMENT: The overcap is placed standing upright on the stone pedestal, to the RIGHT of the bottle and slightly forward. There is a small gap between the bottle and the overcap. The overcap is a tall cylindrical shell in matte black finish — approximately the same height as the spray mechanism portion. The overcap opening faces downward (it sits inverted, dome/top facing up). The overcap diameter matches the bottle body diameter. PEDESTAL: Dark slate gray polished stone slab. Matte finish with subtle surface texture. Slab is wide enough to hold both the bottle and the overcap side by side. Low-profile slab thickness. Both bottle and overcap sit on the stone surface. COMPOSITION: The bottle is centered-left in frame, overcap to the right. 2000x2200px portrait format. The tall bottle occupies 65-70% of canvas height. Breathing room above and below. No other props, no labels, no text. LIGHTING - CHIAROSCURO STUDIO: - Key Light: 45 degree angle upper left, 6200K color temperature, strong directional illumination on the left side of the glass cylinder - Rim Light: Subtle backlight from upper right, thin bright rim along right edge of glass, reveals translucency - Fill Light: 60% intensity from camera left, softens shadows - Shadow: Long soft shadow extending from bottle base across stone surface, feathered edge BACKGROUND: Warm cream color (#F5F3EF) — uniform, soft, no gradients. Seamless backdrop. STYLE: Premium luxury product photography. Photorealistic. Studio-lit precision. Immaculate. CRITICAL CONSTRAINTS: - The bottle body is approximately 3.2:1 H:W ratio — shorter and slightly wider than the 9ml cylinder - The spray mechanism is FULLY MATTE BLACK — not white with a band - The overcap must be SEPARATE from the bottle, placed beside it on the right - The spray nozzle/actuator must be clearly visible on the uncapped bottle - No liquid inside the bottle — completely empty - Do NOT say perfume, spray, or fragrance in any text — this is a product photograph only - The overall silhouette should be a compact, elegant spray bottle — shorter than a 9ml roll-on | G2: Nano Banana Pro | H2: High | I2: 0 | K2: Cap-off series: overcap beside bottle on stone pedestal. Cream bg #F5F3EF. 2000x2200 portrait. Fully colored matte black spray mechanism. Measured body H:W 3.24:1, assembled 4.39:1.
A3: 2 | B3: Cylinder | C3: 5 | D3: Cobalt Blue | E3: Fine Mist Sprayer | F3: Professional e-commerce product photograph of a tall, slender cobalt blue glass 5ml cylinder fine mist spray bottle shown WITHOUT its overcap. The overcap is placed standing upright beside the bottle on the right side, revealing the spray mechanism. EXACT BOTTLE SHAPE: Tall, slender cylinder spray bottle. The glass body height-to-width ratio is approximately 3.1:1. The body is a perfect cylinder with absolutely straight parallel sides — no taper, no bulge, no curves, no waist. Flat bottom sits flush on the stone surface. The spray mechanism extends above the glass body, adding about 22% to the total height. With the sprayer exposed (no overcap), the total height-to-body-width ratio is approximately 4.2:1. The bottle is EMPTY — no liquid inside. SPRAY MECHANISM — critical detail: The fine mist spray pump is FULLY COLORED — the entire mechanism is a single solid shiny silver finish. This is NOT a white sprayer with a colored band — the actuator button, the collar, the tube housing are ALL shiny silver metallic. The spray nozzle points upward. The mechanism sits flush with the glass body diameter. A thin dip tube extends down inside the bottle (barely visible through the deep blue glass). GLASS / MATERIAL: Deep saturated cobalt blue glass — a rich, vivid royal blue. The glass is transparent with the intense blue visible from every angle. Light refracts through showing deep blue tones. The blue color is uniform and saturated throughout the glass walls. No cloudiness, no bubbles, no imperfections. Premium optical clarity. EMPTY — no liquid fill. OVERCAP PLACEMENT: The overcap is placed standing upright on the stone pedestal, to the RIGHT of the bottle and slightly forward. There is a small gap between the bottle and the overcap. The overcap is a tall cylindrical shell in shiny silver metallic finish — approximately the same height as the spray mechanism portion. The overcap opening faces downward (it sits inverted, dome/top facing up). The overcap diameter matches the bottle body diameter. PEDESTAL: Dark slate gray polished stone slab. Matte finish with subtle surface texture. Slab is wide enough to hold both the bottle and the overcap side by side. Low-profile slab thickness. Both bottle and overcap sit on the stone surface. COMPOSITION: The bottle is centered-left in frame, overcap to the right. 2000x2200px portrait format. The tall bottle occupies 65-70% of canvas height. Breathing room above and below. No other props, no labels, no text. LIGHTING - CHIAROSCURO STUDIO: - Key Light: 45 degree angle upper left, 6200K color temperature, strong directional illumination on the left side of the glass cylinder - Rim Light: Subtle backlight from upper right, thin bright rim along right edge of glass, makes the cobalt blue glow - Fill Light: 60% intensity from camera left, softens shadows - Shadow: Long soft shadow extending from bottle base across stone surface, feathered edge BACKGROUND: Warm cream color (#F5F3EF) — uniform, soft, no gradients. Seamless backdrop. STYLE: Premium luxury product photography. Photorealistic. Studio-lit precision. Immaculate. CRITICAL CONSTRAINTS: - The bottle body is approximately 3.1:1 H:W ratio — shorter and slightly wider than the 9ml cylinder - The spray mechanism is FULLY SHINY SILVER — not white with a band - The overcap must be SEPARATE from the bottle, placed beside it on the right - The spray nozzle/actuator must be clearly visible on the uncapped bottle - The cobalt blue glass must be vivid and saturated — not pale or washed out - No liquid inside the bottle — completely empty - Do NOT say perfume, spray, or fragrance in any text — this is a product photograph only - The overall silhouette should be a compact, elegant spray bottle — shorter than a 9ml roll-on | G3: Nano Banana Pro | H3: High | I3: 0 | K3: Cap-off series: overcap beside bottle on stone pedestal. Cream bg #F5F3EF. 2000x2200 portrait. Fully colored shiny silver spray mechanism. Measured body H:W 3.1:1, assembled 4.39:1.

Sheet Gaps & Notes
B1: Gaps, Issues & Notes
B3: Known Gaps
B4: Issue Type | C4: Details | D4: Resolution
B5: Missing Product Group | C5: Pillar 9ml Clear Roll-On (13-415) | D5: addProductGroup mutation ready, needs npx convex deploy
B6: Missing Product Group | C6: Cylinder 30ml Clear Roll-On (18-415) | D6: addProductGroup mutation ready, needs npx convex deploy
B7: Misassigned Products | C7: GB-PIL-CLR-9ML-MRL-BDOT, GB-PIL-CLR-9ML-RBL-BDOT | D7: Roll-on products in cap group; reassign after new group created
B8: Applicator Fix Applied | C8: 92 groups patched (2026-04-06) | D8: Aligned to frontend APPLICATOR_BUCKETS productValues
B10: Pipeline UI Integration
B11: • Pipeline UI app: AI-OS/paper-doll-pipeline/tools/pipeline-ui/ (npm run dev)
B12: • Reads from: /Users/jordanrichter/Desktop/AI-OS/paper-doll-pipeline/output/
B13: • API routes: /api/inventory, /api/families, /api/gallery, /api/images
B14: • Gallery tracks generation modes: sandstone, grid, cap-off, heroes, composited
B15: • Pipeline UI is for Paper Doll (Layer 3) — this tracker is for Grid Images (Layer 1)
B16: • Grid images upload to Sanity CDN → heroImageUrl on Convex productGroups
B18: Data Quality Notes
B19: • applicatorTypes aligned to frontend catalogFilters.ts APPLICATOR_BUCKETS productValues (2026-04-06)
B20: • Multi-value groups: Roll-On groups may have ["Metal Roller Ball","Plastic Roller Ball"]
B21: • Dashboard uses COUNTIF with wildcards (*value*) to handle multi-value applicator cells
B22: • 31 groups have heroImageUrl from prior work; 260 need AI generation
... B26: • All 15 frontend fields now present in tracker columns
