Workbook

Sheet Read me
A1: Best Bottles bottle bodies
A2: Measurements from Convex production (precise-raccoon-123), products table, pulled 2026-09-16 14:30 PDT.
A3: One row per physical glass: the bottle that governs every SKU built on it. Its height without cap is the source of truth for sizing.
A5: Summary
A6: Bottle bodies (glasses) | B6: =COUNTA('Bottle bodies'!B2:B109) | C6: Family + capacity + neck finish + glass finish (standard, frosted, swirl) + tall glass. Glass colour and fitment do not change the body.
A7: SKUs covered | B7: =SUM('Bottle bodies'!N2:N109) | C7: Every live bottle, jar, aluminium, plastic and metal-atomizer SKU. Retired SKUs, caps, components and packaging are excluded.
A8: Families | B8: =COUNTA(A23:A49) | C8: Listed under Bodies per family below.
A9: Status OK | B9: =COUNTIF('Bottle bodies'!S2:S109,"OK") | C9: Every SKU on the glass records the same height without cap.
A10: Heights disagree | B10: =COUNTIF('Bottle bodies'!S2:S109,"Heights disagree") | C10: Most common height is used; the odd SKUs are listed so they can be corrected.
A11: Check height | B11: =COUNTIF('Bottle bodies'!S2:S109,"Check height") | C11: The recorded height cannot be right for the capacity or the photograph.
A12: Some SKUs blank | B12: =COUNTIF('Bottle bodies'!S2:S109,"Some SKUs blank") | C12: The glass has a height, but some of its SKUs have none recorded.
A14: How to read a row
A15: Height without cap (mm) | C15: The source of truth. Bare glass, foot to rim. When SKUs disagree, the value most of them record.
A16: Height with cap, min / max (mm) | C16: Varies with the fitment, so shown as the range across the glass's SKUs.
A17: Governing SKU | C17: The SKU that stands for the glass: records the source-of-truth height, clear glass first, audited measurement first.
A18: Measurement source | C18: master truth = the 2026-07-12 audited master written to production; legacy exact = copied from the legacy site; none = no provenance stamp.
A19: Frosted and swirl | C19: Listed as their own rows because they are different bottles to photograph; several share the clear glass's height.
A20: All SKUs sheet | C20: Every SKU with its body number, so any row can be traced and corrected in Convex.
A22: Bodies per family | B22: Bodies | C22: SKUs
A23: Aluminum Bottle | B23: =COUNTIF('Bottle bodies'!$B$2:$B$109,A23) | C23: =SUMIF('Bottle bodies'!$B$2:$B$109,A23,'Bottle bodies'!$N$2:$N$109)
A24: Apothecary | B24: =COUNTIF('Bottle bodies'!$B$2:$B$109,A24) | C24: =SUMIF('Bottle bodies'!$B$2:$B$109,A24,'Bottle bodies'!$N$2:$N$109)
A25: Atomizer | B25: =COUNTIF('Bottle bodies'!$B$2:$B$109,A25) | C25: =SUMIF('Bottle bodies'!$B$2:$B$109,A25,'Bottle bodies'!$N$2:$N$109)
A26: Bell | B26: =COUNTIF('Bottle bodies'!$B$2:$B$109,A26) | C26: =SUMIF('Bottle bodies'!$B$2:$B$109,A26,'Bottle bodies'!$N$2:$N$109)
A27: Boston Round | B27: =COUNTIF('Bottle bodies'!$B$2:$B$109,A27) | C27: =SUMIF('Bottle bodies'!$B$2:$B$109,A27,'Bottle bodies'!$N$2:$N$109)
A28: Circle | B28: =COUNTIF('Bottle bodies'!$B$2:$B$109,A28) | C28: =SUMIF('Bottle bodies'!$B$2:$B$109,A28,'Bottle bodies'!$N$2:$N$109)
A29: Cream Jar | B29: =COUNTIF('Bottle bodies'!$B$2:$B$109,A29) | C29: =SUMIF('Bottle bodies'!$B$2:$B$109,A29,'Bottle bodies'!$N$2:$N$109)
A30: Cylinder | B30: =COUNTIF('Bottle bodies'!$B$2:$B$109,A30) | C30: =SUMIF('Bottle bodies'!$B$2:$B$109,A30,'Bottle bodies'!$N$2:$N$109)
A31: Decorative | B31: =COUNTIF('Bottle bodies'!$B$2:$B$109,A31) | C31: =SUMIF('Bottle bodies'!$B$2:$B$109,A31,'Bottle bodies'!$N$2:$N$109)
A32: Diamond | B32: =COUNTIF('Bottle bodies'!$B$2:$B$109,A32) | C32: =SUMIF('Bottle bodies'!$B$2:$B$109,A32,'Bottle bodies'!$N$2:$N$109)
A33: Diva | B33: =COUNTIF('Bottle bodies'!$B$2:$B$109,A33) | C33: =SUMIF('Bottle bodies'!$B$2:$B$109,A33,'Bottle bodies'!$N$2:$N$109)
A34: Elegant | B34: =COUNTIF('Bottle bodies'!$B$2:$B$109,A34) | C34: =SUMIF('Bottle bodies'!$B$2:$B$109,A34,'Bottle bodies'!$N$2:$N$109)
... A49: Vial | B49: =COUNTIF('Bottle bodies'!$B$2:$B$109,A49) | C49: =SUMIF('Bottle bodies'!$B$2:$B$109,A49,'Bottle bodies'!$N$2:$N$109)

Sheet Bottle bodies
A1: # | B1: Family | C1: Capacity (ml) | D1: Neck finish | E1: Glass finish | F1: Variant | G1: Height without cap (mm) | H1: Tolerance (± mm) | I1: Height with cap, min (mm) | J1: Height with cap, max (mm) | K1: Diameter (mm) | L1: Governing SKU | M1: Governing product | N1: SKUs on this glass | O1: Glass colours | P1: Heights recorded across its SKUs | Q1: SKUs with a different height | R1: Measurement source | S1: Status | T1: Notes
A2: 1 | B2: Aluminum Bottle | C2: 65 | D2: 20-410 | E2: Standard | G2: 94 | H2: 1 | I2: 127 | J2: 130 | K2: 36 | L2: Alu65mlLotionPumpBlack | M2: Cylinder shaped, brushed aluminum 65 ml bottle with lotion black. For use with lotion or treatment pump. Price Each | N2: 2 | O2: n/a | P2: 94 mm × 2 | R2: master truth × 2 | S2: OK
A3: 2 | B3: Aluminum Bottle | C3: 100 | D3: 20-410 | E3: Standard | G3: 127.8 | I3: 150 | J3: 150 | K3: 50 | L3: Alu100mlSprayBlack | M3: Cylinder shaped, matte aluminum 100 ml bottle with black sprayer. For use with cologne, perfume, air freshner, face and body spray, or room spray. Price Each | N3: 1 | O3: n/a | P3: 127.8 mm × 1 | R3: none × 1 | S3: OK
A4: 3 | B4: Aluminum Bottle | C4: 120 | D4: 20-410 | E4: Standard | G4: 114 | H4: 2 | I4: 147 | J4: 147 | K4: 45 | L4: Alu120mlLotionPumpBlack | M4: Cylinder shaped, brushed aluminum 120 ml bottle with lotion black. For use with lotion or treatment pump. Price Each | N4: 2 | O4: n/a | P4: 114 mm × 2 | R4: master truth × 2 | S4: OK
A5: 4 | B5: Aluminum Bottle | C5: 250 | D5: 20-410 | E5: Standard | G5: 127.8 | I5: 180 | J5: 180 | K5: 60 | L5: Alu250mlSprayBlack | M5: Aluminum Bottle 250 ml (8.45 oz) Clear Aluminum Bottle with Sprayer Black Cap | N5: 1 | O5: Clear | P5: 127.8 mm × 1 | R5: master truth × 1 | S5: OK
A6: 5 | B6: Aluminum Bottle | C6: 500 | D6: 20-410 | E6: Standard | G6: 178 | H6: 2 | I6: 186 | J6: 186 | K6: 74 | L6: Alu500 | M6: Cylinder shaped, aluminum 500 ml bottle with white plug and tear off cap. For use with perfume oil, aromatic oils, fragrance oils and attars. Price Each | N6: 1 | O6: n/a | P6: 178 mm × 1 | R6: master truth × 1 | S6: OK
A7: 6 | B7: Apothecary | C7: 15 | D7: Ground | E7: Standard | G7: 58 | H7: 1 | I7: 82 | J7: 82 | K7: 30 | L7: GB15ApthBlue | M7: Apothecary style 15 ml blue glass bottle with blue glass stopper. For use with perfume or fragrance oil, essential oil, aromatherapy. Good for displaying products. These are hand made bottles with ground glass stoppers. The stoppers are not leak proof, | N7: 1 | O7: Cobalt Blue | P7: 58 mm × 1 | R7: master truth × 1 | S7: OK
A8: 7 | B8: Apothecary | C8: 30 | D8: Ground | E8: Standard | G8: 58 | I8: 98 | J8: 98 | K8: 37 | L8: GB1ozApth | M8: Apothecary style 30ml clear glass bottle with glass stopper. For use with perfume or fragrance oil, essential oil, aromatherapy. Good for displaying products. These are hand made bottles with ground glass stoppers. The stoppers are not leak proof, and wil | N8: 3 | O8: Clear, Cobalt Blue, Green | P8: 58 mm × 3 | R8: master truth × 3 | S8: OK
A9: 8 | B9: Apothecary | C9: 118 | D9: Ground | E9: Standard | F9: Pear | G9: 52.2 | I9: 77.3 | J9: 77.3 | K9: 27.4 | L9: GBPearClear4ozStpr | M9: Apothecary style 4oz Clear Pear Bottle with glass stopper. 118ml (3.99oz). Semi-automatic handmade bottle with proper fitting stopper. Not leak proof. For perfumes and fragrance oils. | N9: 1 | O9: Clear | P9: 52.2 mm × 1 | R9: none × 1 | S9: Check height | T9: a 27.4 x 52.2 mm glass holds about 18 ml, not 118 ml
A10: 9 | B10: Atomizer | C10: 5 | D10: 10mm | E10: Standard | G10: 92 | H10: 1 | I10: 104 | J10: 104 | K10: 15 | L10: GBAtom5SlimGl | M10: Gold slim atomizer design 5 ml bottle. For use with perfumes, Colognes, eau de Parfum. Refillable, travel size atomizer. Can be laser engraved and customized. Great for gifts and promotion. Price each | N10: 3 | O10: Black, Clear | P10: 92 mm × 3 | R10: master truth × 3 | S10: OK
A11: 10 | B11: Atomizer | C11: 5 | D11: 13-415 | E11: Standard | G11: 76 | H11: 1 | I11: 81 | J11: 104 | K11: 18 | L11: GBAtom5Gl | M11: Gold atomizer design 5 ml bottle. For use with perfumes, Colognes, eau de Parfum. Refillable, travel size atomizer. Can be laser engraved and customized. Great for gifts and promotion. Price each | N11: 9 | O11: Black, Clear, Cobalt Blue, Pink | P11: 76 mm × 9 | R11: master truth × 9 | S11: OK
A12: 11 | B12: Atomizer | C12: 10 | D12: 17mm | E12: Standard | G12: 82 | H12: 1 | I12: 89 | J12: 89 | K12: 23 | L12: GBAtom10Gl | M12: Gold atomizer design 10 ml bottle. For use with perfumes, Colognes, eau de Parfum. Refillable, travel size atomizer. Can be laser engraved and customized. Great for gifts and promotion. Price each | N12: 11 | O12: Black, Clear, Cobalt Blue, Green, Pink | P12: 82 mm × 11 | R12: master truth × 11 | S12: OK
A13: 12 | B13: Bell | C13: 10 | D13: 13-415 | E13: Standard | G13: 55 | H13: 1 | I13: 20 | J13: 66 | K13: 27 | L13: GBBell10BlkShSht | M13: Bell design 10ml Clear glass bottle with short shiny black cap. For use with perfume or fragrance oil, essential oils, aromatic oils and aromatherapy. Refillable, classic style bottle good for promotions and decants. Price each | N13: 4 | O13: Clear | P13: 55 mm × 4 | R13: master truth × 4 | S13: OK
A14: 13 | B14: Boston Round | C14: 15 | D14: 18-400 | E14: Standard | G14: 68 | H14: 1 | I14: 72 | J14: 91 | K14: 25 | L14: GBBstn15BlkCapSht | M14: Boston round design 15ml, 1/2 oz Clear glass bottle with short black cap. For use with Perfume oils, essential oils, diffuser oils and aromatherapy. Price each | N14: 16 | O14: Amber, Clear, Cobalt Blue | P14: 68 mm × 16 | R14: master truth × 16 | S14: OK
A15: 14 | B15: Boston Round | C15: 30 | D15: 20-400 | E15: Standard | G15: 78 | H15: 1 | I15: 78 | J15: 102 | K15: 33 | L15: GBBstn1ozBlkDrp | M15: Boston round design 30ml, 1oz Clear glass bottle with black dropper. For use with perfume oils, diffuser oils, serums, primers, facial oils or face oils, moisturizers, and beard oils. Price each | N15: 53 | O15: Amber, Clear, Cobalt Blue | P15: 68 mm × 1; 78 mm × 52 | Q15: GBBstn1ozBlkCapSht (68 mm) | R15: master truth × 52; none × 1 | S15: Heights disagree | T15: most common height used; fix the SKUs listed; all the odd ones are short-cap listings, possibly measured with the cap on
A16: 15 | B16: Boston Round | C16: 60 | D16: 20-400 | E16: Standard | G16: 94 | H16: 1 | I16: 110 | J16: 117 | K16: 39 | L16: GBBstn2ozBlkCapSht | M16: Boston round design 60ml, 2oz Clear glass bottle with short black cap. For use with Perfume oils, essential oils, diffuser oils and aromatherapy. Price each | N16: 55 | O16: Amber, Clear, Cobalt Blue | P16: 94 mm × 55 | R16: master truth × 54; none × 1 | S16: OK
A17: 16 | B17: Circle | C17: 15 | D17: 13-415 | E17: Standard | G17: 60 | H17: 1 | I17: 62 | J17: 80 | K17: 50 | L17: GBCrcl15BlkSht | M17: Circle design 15ml, 1/2oz Clear glass bottle with short black cap. For use with perfume or fragrance oil, essential oils, aromatic oils and aromatherapy. Refillable, classic style bottle good for promotions and decants. Price each | N17: 36 | O17: Clear | P17: 60 mm × 36 | R17: master truth × 30; none × 6 | S17: OK
A18: 17 | B18: Circle | C18: 30 | D18: 15-415 | E18: Standard | G18: 74 | H18: 1 | I18: 93 | J18: 100 | K18: 60 | L18: GBCrcl30GlCap | M18: Circle design 30 ml, clear glass bottle with shiny gold and cap. For use with cologne, perfume or fragrance oil, after shave and beard oils. Price each Classic, Circle design is a family of bottles availabel in many sizes. Price each | N18: 7 | O18: Clear | P18: 74 mm × 7 | R18: master truth × 7 | S18: OK
A19: 18 | B19: Circle | C19: 50 | D19: 18-400 | E19: Frosted | G19: 87 | H19: 1 | I19: 101 | J19: 101 | K19: 72 | L19: GBCrclFrst50RdcrIvyLthr | M19: Circle design 50 ml, 1.7oz frosted glass bottle with reducer and ivoryfaux leather cap. For use with cologne, aftershave, splash on, and perfume or fragrance oil, beard oils. Circle design is a famiily of bottles available in 15ml, 30ml, 50ml and 100ml | N19: 1 | O19: Frosted | P19: 87 mm × 1 | R19: master truth × 1 | S19: OK
A20: 19 | B20: Circle | C20: 50 | D20: 18-415 | E20: Frosted | G20: 87 | H20: 1 | I20: 91 | J20: 115 | K20: 72 | L20: GBCrclFrst50AnSpBlk | M20: Circle design 50 ml, 1.7oz frosted glass bottle with black vintage style bulb sprayer with shiny silver collar cap. For use with cologne, Eau de Parfum, air freshner, face and body spray, or room spray. Antique or vintage bulb sprayers enhance the beau | N20: 44 | O20: Frosted | P20: 87 mm × 44 | R20: master truth × 44 | S20: OK
A21: 20 | B21: Circle | C21: 50 | D21: 18-415 | E21: Standard | G21: 87 | H21: 1 | I21: 91 | J21: 115 | K21: 72 | L21: GBCrcl50AnSpBlk | M21: Circle design 50 ml, 1.7oz clear glass bottle with black vintage style bulb sprayer with shiny silver collar cap. For use with cologne, Eau de Parfum, air freshner, face and body spray, or room spray. Antique or vintage bulb sprayers enhance the beauty | N21: 46 | O21: Clear | P21: 87 mm × 46 | R21: master truth × 46 | S21: OK
A22: 21 | B22: Circle | C22: 100 | D22: 18-415 | E22: Frosted | G22: 105 | H22: 2 | I22: 109 | J22: 136 | K22: 89 | L22: GBCrclFrst100AnSpBlk | M22: Circle design 100 ml, 3 1/2oz frosted glass bottle with black vintage style bulb sprayer with shiny silver collar cap. For use with cologne, Eau de Parfum, air freshner, face and body spray, or room spray. Antique or vintage bulb sprayers enhance the bea | N22: 43 | O22: Frosted | P22: 105 mm × 43 | R22: master truth × 43 | S22: OK
A23: 22 | B23: Circle | C23: 100 | D23: 18-415 | E23: Standard | G23: 105 | H23: 2 | I23: 109 | J23: 136 | K23: 89 | L23: GBCrcl100AnSpBlk | M23: Circle design 100 ml, 3 1/2oz clear glass bottle with black vintage style bulb sprayer with shiny silver collar cap. For use with cologne, Eau de Parfum, air freshner, face and body spray, or room spray. Antique or vintage bulb sprayers enhance the bea | N23: 43 | O23: Clear | P23: 105 mm × 43 | R23: master truth × 43 | S23: OK
A24: 23 | B24: Cream Jar | C24: 3 | D24: 20mm | E24: Standard | G24: 18 | H24: 0.5 | I24: 24 | J24: 50 | K24: 35 | L24: CJBlu3 | M24: Plastic, cream jar style 3 ml bottle with blue cap. For use with body butters, creams, and thick lotions. Small trial or sample size. Great for promotions. Price each | N24: 2 | O24: n/a | P24: 18 mm × 1; 22 mm × 1 | Q24: CJClr3 (22 mm) | R24: master truth × 2 | S24: Heights disagree | T24: most common height used; fix the SKUs listed
A25: 24 | B25: Cream Jar | C25: 5 | D25: 27mm | E25: Standard | G25: 24 | H25: 0.5 | I25: 18 | J25: 28 | K25: 31 | L25: CJAmb5mlBlkCap | M25: Cream glass jar style 5 ml amber bottle with black cap. For use with body butters, creams, and thick lotions. Small trial or sample size. Great for promotions. Price each | N25: 2 | O25: n/a | P25: 16 mm × 1; 24 mm × 1 | Q25: CJClr5mlClrCap (16 mm) | R25: master truth × 2 | S25: Heights disagree | T25: most common height used; fix the SKUs listed
A26: 25 | B26: Cream Jar | C26: 5 | D26: PRESS-FIT | E26: Standard | G26: 24 | H26: 0.5 | I26: 28 | J26: 28 | K26: 31 | L26: CJAmb5mlSlCap | M26: Cream Jar 5 ml (0.17 oz) Amber Glass Silver Cap | N26: 1 | O26: Amber | P26: 24 mm × 1 | R26: master truth × 1 | S26: OK
A27: 26 | B27: Cream Jar | C27: 15 | D27: 37mm | E27: Standard | G27: 26 | H27: 0.5 | I27: 29 | J27: 31 | K27: 55 | L27: CJClr15Pnk | M27: Plastic, cream jar style 15 ml bottle with pink cap. For use with body butters, creams, and thick lotions. Small trial or sample size. Great for promotions. Price each | N27: 2 | O27: n/a | P27: 26 mm × 1; 31 mm × 1 | Q27: CJClr15Wht (31 mm) | R27: master truth × 2 | S27: Heights disagree | T27: most common height used; fix the SKUs listed
A28: 27 | B28: Cream Jar | C28: 20 | D28: 40mm | E28: Standard | G28: 33.9 | I28: 29 | J28: 29 | K28: 55 | L28: CJWhite20 | M28: Plastic, cream jar style 20 mlbottle with white cap. For use with body butters, creams, and thick lotions. Small trial or sample size. Great for promotions. Price each | N28: 1 | O28: n/a | P28: 33.9 mm × 1 | R28: master truth × 1 | S28: OK
A29: 28 | B29: Cream Jar | C29: 30 | D29: 45mm | E29: Standard | G29: 35 | H29: 0.5 | I29: 40 | J29: 40 | K29: 52 | L29: CJAmb30BlkCap | M29: Cream glass jar style 30 ml amber bottle with black cap. For use with body butters, creams, thick lotions. Price each | N29: 4 | O29: n/a | P29: 35 mm × 4 | R29: master truth × 4 | S29: OK
A30: 29 | B30: Cream Jar | C30: 40 | D30: 48/400 | E30: Standard | G30: 42 | H30: 0.5 | I30: 47 | J30: 47 | K30: 56 | L30: CJAmb40SlCap | M30: Glass, cream jar style 40 ml amber bottle with silver cap. For use with body butters, creams, thick lotions. Price each | N30: 4 | O30: n/a | P30: 42 mm × 4 | R30: master truth × 4 | S30: OK
A31: 30 | B31: Cream Jar | C31: 60 | D31: 58mm | E31: Standard | G31: 51 | H31: 1 | I31: 57 | J31: 57 | K31: 59 | L31: CreamJarFrstdPlsBlkPls2oz | M31: Frosted plastic Cream jar bottle with clear cap. Capacity: 63 ml | N31: 1 | O31: n/a | P31: 51 mm × 1 | R31: master truth × 1 | S31: OK
A32: 31 | B32: Cream Jar | C32: 63 | D32: 58mm | E32: Standard | G32: 51 | I32: 57 | J32: 57 | K32: 59 | L32: CJWhitePlsSlFr2oz | M32: White plastic cream jar with silver cap, capacity 63 ml | N32: 1 | O32: n/a | P32: 51 mm × 1 | R32: master truth × 1 | S32: OK
A33: 32 | B33: Cylinder | C33: 3.3 | D33: 12mm | E33: Standard | G33: 37 | H33: 0.5 | I33: 54 | J33: 54 | K33: 14 | L33: GBSpry3mlClBlk | M33: 3.3ml Clear Glass Bottle with Black Spray Pump and Clear Cap. Good for use as a sample. | N33: 2 | O33: Clear | P33: 37 mm × 2 | R33: master truth × 1; legacy exact × 1 | S33: OK
A34: 33 | B34: Cylinder | C34: 4 | D34: 12mm | E34: Standard | G34: 49 | H34: 0.5 | I34: 67 | J34: 67 | K34: 14 | L34: GBSpry4mlClBlk | M34: Clear Glass Bottle with Black Spray Pump and Clear Cap. Capacity: 4ml | N34: 2 | O34: Clear | P34: 49 mm × 2 | R34: master truth × 2 | S34: OK
A35: 34 | B35: Cylinder | C35: 5 | D35: 13-415 | E35: Standard | G35: 53 | H35: 1 | I35: 55 | J35: 80 | K35: 17 | L35: GBCyl5BlkSht | M35: 5 mL Clear Cylinder Bottle with Short Ribbed Black Cap | N35: 70 | O35: Clear, Cobalt Blue | P35: 53 mm × 65; 60 mm × 5 | Q35: GBCylBlu5CuSht (60 mm), GBCylBlu5GlMattSht (60 mm), GBCylBlu5GlSht (60 mm), GBCylBlu5SlMattSht (60 mm), GBCylBlu5SlSht (60 mm) | R35: master truth × 54; none × 11; legacy exact × 5 | S35: Heights disagree | T35: most common height used; fix the SKUs listed; all the odd ones are short-cap listings, possibly measured with the cap on
A36: 35 | B36: Cylinder | C36: 5.5 | D36: 13-415 | E36: Standard | G36: 53 | H36: 1 | I36: 72 | J36: 72 | K36: 17 | L36: GBCyl5SpryBlkMatt | M36: Cylinder design 5.5ml, 1/6oz Clear glass bottle with matte black spray. Fine mist sprayer for use with perfumes and colognes. Refillable, Small sized bottle for decants, promotion, samples and travel accessory. Price each | N36: 1 | O36: Clear | P36: 53 mm × 1 | R36: master truth × 1 | S36: OK | T36: same 53 mm glass as the 5 ml; listed separately as 5.5 ml
A37: 36 | B37: Cylinder | C37: 9 | D37: 13-415 | E37: Frosted | F37: Tall | G37: 106 | H37: 2 | I37: 109 | J37: 126 | K37: 18 | L37: GBTallCylFrst9BlkSht | M37: Tall cylinder design 9ml, 1/3oz frosted glass bottle with short black cap. For use with perfume or fragrance oil, essential oils, aromatic oils and aromatherapy. Refillable, slender bottle with attractive heavy base. Price each | N37: 36 | O37: Frosted | P37: 106 mm × 36 | R37: master truth × 29; none × 6; legacy exact × 1 | S37: OK
A38: 37 | B38: Cylinder | C38: 9 | D38: 13-415 | E38: Standard | F38: Tall | G38: 106 | H38: 2 | I38: 109 | J38: 126 | K38: 18 | L38: GBTallCyl9BlkSht | M38: Tall cylinder design 9ml, 1/3oz Clear glass bottle with short black cap. For use with perfume or fragrance oil, essential oils, aromatic oils and aromatherapy. Refillable, slender bottle with attractive heavy base. Price each | N38: 36 | O38: Clear | P38: 106 mm × 36 | R38: master truth × 30; none × 6 | S38: OK
A39: 38 | B39: Cylinder | C39: 9 | D39: 17-415 | E39: Frosted | G39: 74 | H39: 1 | I39: 87 | J39: 94 | K39: 21 | L39: GBCylFrst9MtlRollBlkDot | M39: Cylinder design 9ml,1/3 oz frosted glass bottle with metal roller ball plug and black dot cap. For use with perfume or fragrance oil, essential oils, aromatic oils and aromatherapy. Price each | N39: 29 | O39: Frosted | P39: 74 mm × 29 | R39: master truth × 20; legacy exact × 9 | S39: OK
A40: 39 | B40: Cylinder | C40: 9 | D40: 17-415 | E40: Standard | G40: 70 | H40: 1 | I40: 83 | J40: 98 | K40: 20 | L40: GBCyl9MtlRollBlkDot | M40: Cylinder design 9ml,1/3 oz clear glass bottle with metal roller ball plug and black dot cap. For use with perfume or fragrance oil, essential oils, aromatic oils and aromatherapy. Price each | N40: 87 | O40: Amber, Clear, Cobalt Blue | P40: 70 mm × 87 | R40: master truth × 60; legacy exact × 27 | S40: OK
...

Sheet All SKUs
A1: Body # | B1: Family | C1: Capacity (ml) | D1: Neck finish | E1: Glass finish | F1: Glass colour | G1: Applicator | H1: Cap colour | I1: Cap height | J1: Height without cap (mm) | K1: Height with cap (mm) | L1: Diameter (mm) | M1: Height as recorded | N1: Measurement source | O1: Website SKU | P1: Grace SKU | Q1: Product
A2: 1 | B2: Aluminum Bottle | C2: 65 | D2: 20-410 | E2: Standard | H2: Black | J2: 94 | K2: 130 | L2: 36 | M2: 94 ±1 mm | N2: master truth 2026-07-12 | O2: Alu65mlLotionPumpBlack | P2: AB-ALU-CLR-65ML-LPM-BLK | Q2: Cylinder shaped, brushed aluminum 65 ml bottle with lotion black. For use with lotion or treatment pump. Price Each
A3: 1 | B3: Aluminum Bottle | C3: 65 | D3: 20-410 | E3: Standard | H3: White | J3: 94 | K3: 127 | L3: 36 | M3: 94 ±1 mm | N3: master truth 2026-07-12 | O3: Alu65mlLotionPumpWhite | P3: AB-CYL-WHT-65ML-LPM-WHT | Q3: Cylinder shaped, brushed aluminum 65 ml bottle with lotion white. For use with lotion or treatment pump. Price Each
A4: 2 | B4: Aluminum Bottle | C4: 100 | D4: 20-410 | E4: Standard | H4: Black | J4: 127.8 | K4: 150 | L4: 50 | M4: 127.8 | N4: none | O4: Alu100mlSprayBlack | P4: AB-ALU-CLR-100ML-SPR-BLK | Q4: Cylinder shaped, matte aluminum 100 ml bottle with black sprayer. For use with cologne, perfume, air freshner, face and body spray, or room spray. Price Each
A5: 3 | B5: Aluminum Bottle | C5: 120 | D5: 20-410 | E5: Standard | H5: Black | J5: 114 | K5: 147 | L5: 45 | M5: 114 ±2 mm | N5: master truth 2026-07-12 | O5: Alu120mlLotionPumpBlack | P5: AB-ALU-CLR-120ML-LPM-BLK | Q5: Cylinder shaped, brushed aluminum 120 ml bottle with lotion black. For use with lotion or treatment pump. Price Each
A6: 3 | B6: Aluminum Bottle | C6: 120 | D6: 20-410 | E6: Standard | H6: White | J6: 114 | K6: 147 | L6: 45 | M6: 114 ±2 mm | N6: master truth 2026-07-12 | O6: Alu120mlLotionPumpWhite | P6: AB-ALU-CLR-120ML-LPM-WHT | Q6: Cylinder shaped, brushed aluminum 120 ml bottle with lotion white. For use with lotion or treatment pump. Price Each
A7: 4 | B7: Aluminum Bottle | C7: 250 | D7: 20-410 | E7: Standard | F7: Clear | G7: Fine Mist Sprayer | H7: Black | J7: 127.8 | K7: 180 | L7: 60 | M7: 127.8 | N7: master truth 2026-07-12 | O7: Alu250mlSprayBlack | P7: AB-ALU-CLR-250ML-SPR-BLK | Q7: Aluminum Bottle 250 ml (8.45 oz) Clear Aluminum Bottle with Sprayer Black Cap
A8: 5 | B8: Aluminum Bottle | C8: 500 | D8: 20-410 | E8: Standard | H8: Clear | J8: 178 | K8: 186 | L8: 74 | M8: 178 ±2 mm | N8: master truth 2026-07-12 | O8: Alu500 | P8: AB-ALU-CLR-500ML | Q8: Cylinder shaped, aluminum 500 ml bottle with white plug and tear off cap. For use with perfume oil, aromatic oils, fragrance oils and attars. Price Each
A9: 6 | B9: Apothecary | C9: 15 | D9: Ground | E9: Standard | F9: Cobalt Blue | G9: Glass Stopper | H9: Blue | J9: 58 | K9: 82 | L9: 30 | M9: 58 ±1 mm | N9: master truth 2026-07-12 | O9: GB15ApthBlue | P9: GB-APT-BLU-15ML-BLU-T | Q9: Apothecary style 15 ml blue glass bottle with blue glass stopper. For use with perfume or fragrance oil, essential oil, aromatherapy. Good for displaying products. These are hand made bottles with ground glass stoppers. The stoppers are not leak proof,
A10: 7 | B10: Apothecary | C10: 30 | D10: Ground | E10: Standard | F10: Clear | G10: Glass Stopper | H10: Clear | J10: 58 | K10: 98 | L10: 37 | M10: 58 | N10: master truth 2026-07-12 | O10: GB1ozApth | P10: GB-APT-CLR-30ML-T | Q10: Apothecary style 30ml clear glass bottle with glass stopper. For use with perfume or fragrance oil, essential oil, aromatherapy. Good for displaying products. These are hand made bottles with ground glass stoppers. The stoppers are not leak proof, and wil
A11: 7 | B11: Apothecary | C11: 30 | D11: Ground | E11: Standard | F11: Cobalt Blue | G11: Glass Stopper | H11: Blue | J11: 58 | K11: 98 | L11: 37 | M11: 58 | N11: master truth 2026-07-12 | O11: GB1ozApthBlue | P11: GB-APT-BLU-30ML-BLU-T | Q11: Apothecary style 30ml blue glass bottle with blue glass stopper. For use with perfume or fragrance oil, essential oil, aromatherapy. Good for displaying products. These are hand made bottles with ground glass stoppers. The stoppers are not leak proof, and
A12: 7 | B12: Apothecary | C12: 30 | D12: Ground | E12: Standard | F12: Green | G12: Glass Stopper | H12: Green | J12: 58 | K12: 98 | L12: 37 | M12: 58 | N12: master truth 2026-07-12 | O12: GB1ozApthGreen | P12: GB-APT-GRN-30ML-GRN-T | Q12: Apothecary style 30ml green glass bottle with green glass stopper. For use with perfume or fragrance oil, essential oil, aromatherapy. Good for displaying products. These are hand made bottles with ground glass stoppers. The stoppers are not leak proof, a
A13: 8 | B13: Apothecary | C13: 118 | D13: Ground | E13: Standard | F13: Clear | H13: Clear | J13: 52.2 | K13: 77.3 | L13: 27.4 | M13: 52.2 | N13: none | O13: GBPearClear4ozStpr | P13: GB-DEC-CLR-118ML | Q13: Apothecary style 4oz Clear Pear Bottle with glass stopper. 118ml (3.99oz). Semi-automatic handmade bottle with proper fitting stopper. Not leak proof. For perfumes and fragrance oils.
A14: 9 | B14: Atomizer | C14: 5 | D14: 10mm | E14: Standard | F14: Black | G14: Atomizer | H14: Black | J14: 92 | K14: 104 | L14: 15 | M14: 92 ±1 mm | N14: master truth 2026-07-12 | O14: GBAtom5SlimBlk | P14: GB-SLM-BLK-5ML-ATM-BLK-T | Q14: Black slim atomizer design 5 ml bottle. For use with perfumes, Colognes, eau de Parfum. Refillable, travel size atomizer. Can be laser engraved and customized. Great for gifts and promotion. Price each
A15: 9 | B15: Atomizer | C15: 5 | D15: 10mm | E15: Standard | F15: Clear | G15: Atomizer | H15: Gold | J15: 92 | K15: 104 | L15: 15 | M15: 92 ±1 mm | N15: master truth 2026-07-12 | O15: GBAtom5SlimGl | P15: GB-SLM-CLR-5ML-ATM-GLD-T | Q15: Gold slim atomizer design 5 ml bottle. For use with perfumes, Colognes, eau de Parfum. Refillable, travel size atomizer. Can be laser engraved and customized. Great for gifts and promotion. Price each
A16: 9 | B16: Atomizer | C16: 5 | D16: 10mm | E16: Standard | F16: Clear | G16: Atomizer | H16: Silver | J16: 92 | K16: 104 | L16: 15 | M16: 92 ±1 mm | N16: master truth 2026-07-12 | O16: GBAtom5SlimSl | P16: GB-SLM-CLR-5ML-ATM-SLV-T | Q16: Silver slim atomizer design 5 ml bottle. For use with perfumes, Colognes, eau de Parfum. Refillable, travel size atomizer. Can be laser engraved and customized. Great for gifts and promotion. Price each
A17: 10 | B17: Atomizer | C17: 5 | D17: 13-415 | E17: Standard | F17: Black | G17: Atomizer | H17: Black | J17: 76 | K17: 81 | L17: 18 | M17: 76 ±1 mm | N17: master truth 2026-07-12 | O17: GBAtom5Blk | P17: GB-CYL-BLK-5ML-ATM-BLK | Q17: Black atomizer design 5 ml bottle. For use with perfumes, Colognes, eau de Parfum. Refillable, travel size atomizer. Can be laser engraved and customized. Great for gifts and promotion. Price each
A18: 10 | B18: Atomizer | C18: 5 | D18: 13-415 | E18: Standard | F18: Black | G18: Atomizer | H18: Black | J18: 76 | K18: 81 | L18: 18 | M18: 76 ±1 mm | N18: master truth 2026-07-12 | O18: GBAtom5BlkDot | P18: GB-CYL-BLK-5ML-ATM-BLK-02 | Q18: Black atomizer design 5 ml bottle with dots.
A19: 10 | B19: Atomizer | C19: 5 | D19: 13-415 | E19: Standard | F19: Cobalt Blue | G19: Atomizer | H19: Blue | J19: 76 | K19: 81 | L19: 18 | M19: 76 ±1 mm | N19: master truth 2026-07-12 | O19: GBAtom5Blu | P19: GB-CYL-BLU-5ML-ATM-BLU | Q19: Blue atomizer design 5 ml bottle. For use with perfumes, Colognes, eau de Parfum. Refillable, travel size atomizer. Can be laser engraved and customized. Great for gifts and promotion. Price each
A20: 10 | B20: Atomizer | C20: 5 | D20: 13-415 | E20: Standard | F20: Clear | G20: Atomizer | H20: Gold | J20: 76 | K20: 81 | L20: 18 | M20: 76 ±1 mm | N20: master truth 2026-07-12 | O20: GBAtom5Gl | P20: GB-CYL-CLR-5ML-ATM-GLD | Q20: Gold atomizer design 5 ml bottle. For use with perfumes, Colognes, eau de Parfum. Refillable, travel size atomizer. Can be laser engraved and customized. Great for gifts and promotion. Price each
A21: 10 | B21: Atomizer | C21: 5 | D21: 13-415 | E21: Standard | F21: Pink | G21: Atomizer | H21: Pink | J21: 76 | K21: 81 | L21: 18 | M21: 76 ±1 mm | N21: master truth 2026-07-12 | O21: GBAtom5PnkDot | P21: GB-CYL-PNK-5ML-ATM-PNK-02 | Q21: Pink atomizer design 5 ml bottle with dots.
A22: 10 | B22: Atomizer | C22: 5 | D22: 13-415 | E22: Standard | F22: Clear | G22: Atomizer | H22: Red | J22: 76 | K22: 81 | L22: 18 | M22: 76 ±1 mm | N22: master truth 2026-07-12 | O22: GBAtom5Red | P22: GB-CYL-CLR-5ML-ATM-RED | Q22: Red atomizer design 5 ml bottle. For use with perfumes, Colognes, eau de Parfum. Refillable, travel size atomizer. Can be laser engraved and customized. Great for gifts and promotion. Price each
A23: 10 | B23: Atomizer | C23: 5 | D23: 13-415 | E23: Standard | F23: Clear | G23: Atomizer | H23: Silver | J23: 76 | K23: 81 | L23: 18 | M23: 76 ±1 mm | N23: master truth 2026-07-12 | O23: GBAtom5Sl | P23: GB-CYL-CLR-5ML-ATM-SLV-01 | Q23: Silver atomizer design 5 ml bottle. For use with perfumes, Colognes, eau de Parfum. Refillable, travel size atomizer. Can be laser engraved and customized. Great for gifts and promotion. Price each
A24: 10 | B24: Atomizer | C24: 5 | D24: 13-415 | E24: Standard | F24: Clear | G24: Atomizer | H24: Silver | J24: 76 | K24: 104 | L24: 18 | M24: 76 ±1 mm | N24: master truth 2026-07-12 | O24: GBAtom5SlDot | P24: GB-CYL-CLR-5ML-ATM-SLV-02 | Q24: Silver atomizer and sprayer with dots, design 5 ml bottle with dots. For use with perfumes, Colognes, eau de Parfum. Refillable, travel size atomizer. Can be laser engraved and customized. Great for gifts and promotion. Price each
A25: 10 | B25: Atomizer | C25: 5 | D25: 13-415 | E25: Standard | F25: Clear | G25: Atomizer | H25: Silver | J25: 76 | K25: 81 | L25: 18 | M25: 76 ±1 mm | N25: master truth 2026-07-12 | O25: GBAtom5SlStars | P25: GB-CYL-CLR-5ML-ATM-SLV-03 | Q25: Silver atomizer design 5 ml bottle with star patterns. For use with perfumes, Colognes, eau de Parfum. Refillable, travel size atomizer. Can be laser engraved and customized. Great for gifts and promotion. Price each
... A40: 12 | B40: Bell | C40: 10 | D40: 13-415 | E40: Standard | F40: Clear | G40: Fine Mist Sprayer | H40: Shiny Black | J40: 55 | K40: 20 | L40: 27 | M40: 55 ±1 mm | N40: master truth 2026-07-12 | O40: GBBell10SpryBlkSh | P40: GB-BEL-CLR-10ML-SPR-SBLK | Q40: Bell design 10ml Clear glass bottle with shiny black spray. Fine mist sprayer for use with perfumes and colognes. Refillable, classic style bottle good for promotions and decants. Price each
A41: 13 | B41: Boston Round | C41: 15 | D41: 18-400 | E41: Standard | F41: Clear | H41: Black | J41: 68 | K41: 72 | L41: 25 | M41: 68 ±1 mm | N41: master truth 2026-07-12 | O41: GBBstn15BlkCapSht | P41: GB-BSR-CLR-15ML-BLK-S | Q41: Boston round design 15ml, 1/2 oz Clear glass bottle with short black cap. For use with Perfume oils, essential oils, diffuser oils and aromatherapy. Price each
A42: 13 | B42: Boston Round | C42: 15 | D42: 18-400 | E42: Standard | F42: Clear | G42: N/A | J42: 68 | K42: 91 | L42: 25 | M42: 68 ±1 mm Item Diameter: 25 ±0. | N42: master truth 2026-07-12 | O42: GBBstn15BlkDrp | P42: GB-BSR-CLR-15ML-DRP-BLK | Q42: Boston round design 15ml, 1/2 oz Clear glass bottle with a black dropper. For use with perfume oils, diffuser oils, ser
A43: 13 | B43: Boston Round | C43: 15 | D43: 18-400 | E43: Standard | F43: Amber | H43: Black | J43: 68 | K43: 72 | L43: 25 | M43: 68 ±1 mm | N43: master truth 2026-07-12 | O43: GBBstnAmb15mlBlkCapSht | P43: GB-BSR-AMB-15ML-BLK-S | Q43: Boston round design 15ml, 1/2 oz Amber glass bottle with short black cap. For use with Perfume oils, essential oils, diffuser oils and aromatherapy. Price each
A44: 13 | B44: Boston Round | C44: 15 | D44: 18-400 | E44: Standard | F44: Amber | G44: Dropper | H44: Black | J44: 68 | K44: 91 | L44: 25 | M44: 68 ±1 mm | N44: master truth 2026-07-12 | O44: GBBstnAmb15mlBlkDropper | P44: GB-BSR-AMB-15ML-BLK-T-01 | Q44: Boston round design 15ml, 1/2 oz Amber glass bottle with a black dropper. For use with perfume oils, diffuser oils, serums, primers, facial oils or face oils, moisturizers, and beard oils. Price each
A45: 13 | B45: Boston Round | C45: 15 | D45: 18-400 | E45: Standard | F45: Amber | G45: Dropper | H45: Black | J45: 68 | K45: 91 | L45: 25 | M45: 68 ±1 mm | N45: master truth 2026-07-12 | O45: GBBstnAmb15mlBlkDropperGlTrim | P45: GB-BSR-AMB-15ML-BLK-T-02 | Q45: Boston round design 15ml, 1/2 oz Amber glass bottle with black dropper with a shiny gold trim cap. For use with perfume oils, diffuser oils, serums, primers, facial oils or face oils, moisturizers, and beard oils. Price each
A46: 13 | B46: Boston Round | C46: 15 | D46: 18-400 | E46: Standard | F46: Amber | G46: Dropper | H46: Black | J46: 68 | K46: 91 | L46: 25 | M46: 68 ±1 mm | N46: master truth 2026-07-12 | O46: GBBstnAmb15mlBlkDropperSlTrim | P46: GB-BSR-AMB-15ML-BLK-T-03 | Q46: Boston round design 15ml, 1/2 oz Amber glass bottle and black dropper with a shiny silver trim cap. For use with perfume oils, diffuser oils, serums, primers, facial oils or face oils, moisturizers, and beard oils. Price each
A47: 13 | B47: Boston Round | C47: 15 | D47: 18-400 | E47: Standard | F47: Amber | G47: Dropper | H47: White | J47: 68 | K47: 91 | L47: 25 | M47: 68 ±1 mm | N47: master truth 2026-07-12 | O47: GBBstnAmb15mlWhtDropper | P47: GB-BSR-AMB-15ML-WHT-T-01 | Q47: Boston round design 15ml, 1/2 oz Amber glass bottle with a white dropper. For use with perfume oils, diffuser oils, serums, primers, facial oils or face oils, moisturizers, and beard oils. Price each
A48: 13 | B48: Boston Round | C48: 15 | D48: 18-400 | E48: Standard | F48: Amber | G48: Dropper | H48: White | J48: 68 | K48: 91 | L48: 25 | M48: 68 ±1 mm | N48: master truth 2026-07-12 | O48: GBBstnAmb15mlWhtDropperGlTrim | P48: GB-BSR-AMB-15ML-WHT-T-02 | Q48: Boston round design 15ml, 1/2 oz Amber glass bottle and white dropper with a shiny gold trim cap. For use with perfume oils, diffuser oils, serums, primers, facial oils or face oils, moisturizers, and beard oils. Price each
A49: 13 | B49: Boston Round | C49: 15 | D49: 18-400 | E49: Standard | F49: Amber | G49: Dropper | H49: White | J49: 68 | K49: 91 | L49: 25 | M49: 68 ±1 mm | N49: master truth 2026-07-12 | O49: GBBstnAmb15mlWhtDropperSlTrim | P49: GB-BSR-AMB-15ML-WHT-T-03 | Q49: Boston round design 15ml, 1/2 oz Amber glass bottle and white dropper with a shiny silver trim cap. For use with perfume oils, diffuser oils, serums, primers, facial oils or face oils, moisturizers, and beard oils. Price each
A50: 13 | B50: Boston Round | C50: 15 | D50: 18-400 | E50: Standard | F50: Cobalt Blue | H50: Black | J50: 68 | K50: 72 | L50: 25 | M50: 68 ±1 mm | N50: master truth 2026-07-12 | O50: GBBstnBlu15BlkCapSht | P50: GB-BSR-CBL-15ML-BLK-S | Q50: Boston round design 15ml, 1/2 oz Cobalt blue glass bottle with short black cap. For use with Perfume oils, essential oils, diffuser oils and aromatherapy. Price each
A51: 13 | B51: Boston Round | C51: 15 | D51: 18-400 | E51: Standard | F51: Cobalt Blue | G51: Dropper | H51: Black | J51: 68 | K51: 91 | L51: 25 | M51: 68 ±1 mm | N51: master truth 2026-07-12 | O51: GBBstnBlu15BlkDrpr | P51: GB-BSR-CBL-15ML-BLK-T-01 | Q51: Boston round design 15ml, 1/2 oz Cobalt blue glass bottle with a black dropper. For use with perfume oils, diffuser oils, serums, primers, facial oils or face oils, moisturizers, and beard oils. Price each
A52: 13 | B52: Boston Round | C52: 15 | D52: 18-400 | E52: Standard | F52: Cobalt Blue | G52: Dropper | H52: Black | J52: 68 | K52: 91 | L52: 25 | M52: 68 ±1 mm | N52: master truth 2026-07-12 | O52: GBBstnBlu15BlkDrprGlTrim | P52: GB-BSR-CBL-15ML-BLK-T-02 | Q52: Boston round design 15ml, 1/2 oz Cobalt blue glass bottle with black dropper shiny gold trim cap. For use with perfume oils, diffuser oils, serums, primers, facial oils or face oils, moisturizers, and beard oils. Price each
A53: 13 | B53: Boston Round | C53: 15 | D53: 18-400 | E53: Standard | F53: Cobalt Blue | G53: Dropper | H53: White | J53: 68 | K53: 91 | L53: 25 | M53: 68 ±1 mm | N53: master truth 2026-07-12 | O53: GBBstnBlu15WhtDrpr | P53: GB-BSR-CBL-15ML-WHT-T-01 | Q53: Boston round design 15ml, 1/2 oz Cobalt blue glass bottle with a white dropper. For use with perfume oils, diffuser oils, serums, primers, facial oils or face oils, moisturizers, and beard oils. Price each
A54: 13 | B54: Boston Round | C54: 15 | D54: 18-400 | E54: Standard | F54: Cobalt Blue | G54: Dropper | H54: White | J54: 68 | K54: 91 | L54: 25 | M54: 68 ±1 mm | N54: master truth 2026-07-12 | O54: GBBstnBlu15WhtDrprGlTrim | P54: GB-BSR-CBL-15ML-WHT-T-02 | Q54: Boston round design 15ml, 1/2 oz Cobalt blue glass bottle and white dropper and a shiny gold trim cap. For use with perfume oils, diffuser oils, serums, primers, facial oils or face oils, moisturizers, and beard oils. Price each
...
