Workbook

Sheet Start here
B2: Bottle heights: please check
B3: These are the bottle measurements the new website uses to size every product photo. Taken from our product database (Convex) on 2026-09-16.
B5: What to do
B6: 1 Issues to fix (red tab) | D6: 19 bottles where our numbers disagree or can't be right. Each row asks one question and names the SKUs. Please answer these first.
B7: 2 All bottles | D7: The other 89 bottles. Pick Correct / Wrong / Not sure for each one; if Wrong, type the right number. Start with the rows marked High volume.
B8: 3 Send the file back | D8: Reply to the email with this file attached. Please don't rename, delete or re-order rows: the Bottle # is how your answers are loaded back.
B10: How to fill it in
B11: Yellow cells | D11: The only cells to type in. Pick from the dropdown where there is one. Measurements in millimetres, numbers only (e.g. 70 or 50.8).
B12: Red rows | D12: On the All bottles tab, a red row is one of the 19 issues: answer it on the Issues to fix tab instead.
B14: What we measure
B15: Height without cap | D15: Bare glass, from the bottom of the bottle to the top of the neck. Nothing fitted: no cap, sprayer, pump or roller.
B16: Height with cap | D16: The bottle with its cap or fitment on, bottom to the very top.
B17: Diameter | D17: The widest part of the bottle.
B18: One bottle, many SKUs | D18: Every SKU built on the same glass (clear, amber, cobalt; any cap or fitment) must have the same height without cap.
B20: Example of a filled-in issue (not real data)
B21: Right height without cap (mm) | D21: 53
B22: Right height with cap (mm) | D22: 72
B23: Right diameter (mm) | D23: 17
B24: The odd SKUs are | D24: A typo, same bottle
B25: How you checked | D25: Measured a sample
B26: Comment | D26: Same bottle as the rest. The 60 mm figure was measured with the cap on.
B28: Progress
B29: Issues answered | C29: =COUNTIF('Issues to fix'!R2:R20,"Answered") | D29: of 19
B30: Bottles confirmed correct | C30: =COUNTIF('All bottles'!Q2:Q109,"Confirmed") | D30: of 89
B31: Bottles with a correction | C31: =COUNTIF('All bottles'!Q2:Q109,"Correction given")
B32: Bottles marked not sure | C32: =COUNTIF('All bottles'!Q2:Q109,"Not sure")
B33: Bottles still to check | C33: =COUNTIF('All bottles'!Q2:Q109,"To check")

Sheet Issues to fix
A1: Bottle # | B1: Issue | C1: Bottle | D1: Question for you | E1: SKUs involved | F1: Governing SKU | G1: Height without cap now (mm) | H1: Height with cap now (mm) | I1: Diameter now (mm) | J1: SKUs on this bottle | K1: Right height without cap (mm) | L1: Right height with cap (mm) | M1: Right diameter (mm) | N1: Right capacity (ml) | O1: The odd SKUs are | P1: How you checked | Q1: Comment | R1: Answered?
A2: 43 | B2: Height can't be right | C2: Cylinder · 30 ml · 18-415 · Standard | D2: Convex says 50.8 mm tall and 42 mm wide, but this is a slim 30 ml spray tube. What are its real height and diameter? | E2: all: GBSpry1ozGl, GBSpry1ozSl | F2: GBSpry1ozGl | G2: 50.8 | H2: 70.7 | I2: 42 | J2: 2 | R2: =IF(COUNTA(K2:Q2)=0,"To answer",IF(AND(K2="",Q2=""),"Add the right height","Answered"))
A3: 8 | B3: Height can't be right | C3: Apothecary · 118 ml · Ground · Standard · Pear | D3: Convex says 52.2 mm tall and 27.4 mm wide. A glass that size holds about 18 ml, not 118 ml. Is the height or the capacity wrong? | E3: all: GBPearClear4ozStpr | F3: GBPearClear4ozStpr | G3: 52.2 | H3: 77.3 | I3: 27.4 | J3: 1 | R3: =IF(COUNTA(K3:Q3)=0,"To answer",IF(AND(K3="",Q3=""),"Add the right height","Answered"))
A4: 75 | B4: Height can't be right | C4: Lotion Bottle · 3 ml · snap · Standard | D4: Convex says 118 mm tall and 33 mm wide. A glass that size holds about 61 ml, not 3 ml. Is the height or the capacity wrong? | E4: all: LB3mlClear | F4: LB3mlClear | G4: 118 | H4: 124 | I4: 33 | J4: 1 | R4: =IF(COUNTA(K4:Q4)=0,"To answer",IF(AND(K4="",Q4=""),"Add the right height","Answered"))
A5: 34 | B5: Two heights on one bottle | C5: Cylinder · 5 ml · 13-415 · Standard | D5: 65 SKUs say 53 mm; 5 say 60 mm. All the odd ones are short-cap listings: were they measured with the cap on? | E5: 60 mm: GBCylBlu5CuSht, GBCylBlu5GlMattSht, GBCylBlu5GlSht, GBCylBlu5SlMattSht, GBCylBlu5SlSht | F5: GBCyl5BlkSht | G5: 53 | H5: 55–80 | I5: 17 | J5: 70 | R5: =IF(COUNTA(K5:Q5)=0,"To answer",IF(AND(K5="",Q5=""),"Add the right height","Answered"))
A6: 14 | B6: Two heights on one bottle | C6: Boston Round · 30 ml · 20-400 · Standard | D6: 52 SKUs say 78 mm; 1 says 68 mm. The odd one is a short-cap listing: was it measured with the cap on? | E6: 68 mm: GBBstn1ozBlkCapSht | F6: GBBstn1ozBlkDrp | G6: 78 | H6: 78–102 | I6: 33 | J6: 53 | R6: =IF(COUNTA(K6:Q6)=0,"To answer",IF(AND(K6="",Q6=""),"Add the right height","Answered"))
A7: 67 | B7: Two heights on one bottle | C7: Elegant · 60 ml · 18-415 · Frosted | D7: 46 SKUs say 86 mm; 1 says 86.9 mm. Is the odd one a typo, or a different bottle? | E7: 86.9 mm: GBElgFrst60DrpSl | F7: GBElgFrst60AnSpBlk | G7: 86 | H7: 90–135 | I7: 54 | J7: 47 | R7: =IF(COUNTA(K7:Q7)=0,"To answer",IF(AND(K7="",Q7=""),"Add the right height","Answered"))
A8: 68 | B8: Two heights on one bottle | C8: Elegant · 60 ml · 18-415 · Standard | D8: 45 SKUs say 86 mm; 2 say 86.9 mm. Are the odd ones typos, or a different bottle? | E8: 86.9 mm: GBElg60DrpGl, GBElg60DrpSl | F8: GBElg60AnSpBlk | G8: 86 | H8: 90–117 | I8: 54 | J8: 47 | R8: =IF(COUNTA(K8:Q8)=0,"To answer",IF(AND(K8="",Q8=""),"Add the right height","Answered"))
A9: 87 | B9: Two heights on one bottle | C9: Round · 128 ml · 18-415 · Frosted | D9: 43 SKUs say 83 mm; 1 says 78.7 mm; 1 says 83.6 mm; 1 says 110 mm. Are the odd ones typos, or a different bottle? | E9: 78.7 mm: GBRndFrst128DrpGl 83.6 mm: GBRndFrst128DrpSl 110 mm: GBRndFrst128AnSpWht | F9: GBRndFrst128AnSpBlk | G9: 83 | H9: 87–135 | I9: 69 | J9: 46 | R9: =IF(COUNTA(K9:Q9)=0,"To answer",IF(AND(K9="",Q9=""),"Add the right height","Answered"))
A10: 88 | B10: Two heights on one bottle | C10: Round · 128 ml · 18-415 · Standard | D10: 43 SKUs say 83 mm; 2 say 83.6 mm; 1 says 110 mm. Are the odd ones typos, or a different bottle? | E10: 83.6 mm: GBRnd128DrpGl, GBRnd128DrpSl 110 mm: GBRnd128AnSpWht | F10: GBRnd128AnSpBlk | G10: 83 | H10: 87–135 | I10: 69 | J10: 46 | R10: =IF(COUNTA(K10:Q10)=0,"To answer",IF(AND(K10="",Q10=""),"Add the right height","Answered"))
A11: 60 | B11: Two heights on one bottle | C11: Diva · 46 ml · 18-415 · Frosted | D11: 43 SKUs say 89 mm; 1 says 88 mm. Is the odd one a typo, or a different bottle? | E11: 88 mm: GBDivaFrst46AnSpWht | F11: GBDiva46DrpSl | G11: 89 | H11: 93–116 | I11: 49 | J11: 44 | R11: =IF(COUNTA(K11:Q11)=0,"To answer",IF(AND(K11="",Q11=""),"Add the right height","Answered"))
A12: 85 | B12: Two heights on one bottle | C12: Round · 78 ml · 18-415 · Frosted | D12: 42 SKUs say 73 mm; 1 says 100 mm. Is the odd one a typo, or a different bottle? | E12: 100 mm: GBRndFrst78AnSpWht | F12: GBRndFrst78AnSpBlk | G12: 73 | H12: 77–131 | I12: 59 | J12: 43 | R12: =IF(COUNTA(K12:Q12)=0,"To answer",IF(AND(K12="",Q12=""),"Add the right height","Answered"))
A13: 86 | B13: Two heights on one bottle | C13: Round · 78 ml · 18-415 · Standard | D13: 42 SKUs say 73 mm; 1 says 100 mm. Is the odd one a typo, or a different bottle? | E13: 100 mm: GBRnd78AnSpWht | F13: GBRnd78AnSpBlk | G13: 73 | H13: 77–131 | I13: 59 | J13: 43 | R13: =IF(COUNTA(K13:Q13)=0,"To answer",IF(AND(K13="",Q13=""),"Add the right height","Answered"))
A14: 63 | B14: Two heights on one bottle | C14: Elegant · 15 ml · 13-415 · Frosted | D14: 31 SKUs say 61 mm; 5 say 70 mm. All the odd ones are short-cap listings: were they measured with the cap on? | E14: 70 mm: GBElgFrst15CuSht, GBElgFrst15GlMattSht, GBElgFrst15GlSht, GBElgFrst15SlMattSht, GBElgFrst15SlSht | F14: GBElgFrst15BlkShSht | G14: 61 | H14: 66–95 | I14: 35 | J14: 36 | R14: =IF(COUNTA(K14:Q14)=0,"To answer",IF(AND(K14="",Q14=""),"Add the right height","Answered"))
A15: 56 | B15: Two heights on one bottle | C15: Decorative · 35 ml · Ground · Standard · Eternal Flame | D15: 2 SKUs say 44 mm; 1 says 43 mm. Is the odd one a typo, or a different bottle? | E15: 44 mm: GBEternalFlameClear, GBEternalFlameGreen 43 mm: GBEternalFlameBlue | F15: GBEternalFlameClear | G15: 44 | H15: 80–82 | I15: 63 | J15: 3 | R15: =IF(COUNTA(K15:Q15)=0,"To answer",IF(AND(K15="",Q15=""),"Add the right height","Answered"))
A16: 106 | B16: Two heights on one bottle | C16: Vial · 3 ml · 13-425 · Standard | D16: 2 SKUs say 29 mm; 1 says 27 mm. The odd one is a short-cap listing: was it measured with the cap on? | E16: 29 mm: GBVGreen2o4BlackCapSht, GBVGreen2o4WhtCapSht 27 mm: GBVBlu1o9BlackCapSht | F16: GBVGreen2o4BlackCapSht | G16: 29 | H16: 20–75 | I16: 14 | J16: 3 | R16: =IF(COUNTA(K16:Q16)=0,"To answer",IF(AND(K16="",Q16=""),"Add the right height","Answered"))
... A20: 41 | B20: Height missing | C20: Cylinder · 25 ml · 18-415 · Standard | D20: 30 of 45 SKUs have no height recorded; the rest say 83 mm. Is 83 mm right for all of them? | E20: blank (30): GBCyl25AnSpBlk, GBCyl25AnSpGl, GBCyl25AnSpTslIvySl, GBCyl25AnSpTslMtSl, GBCyl25AnSpTslRed, GBCyl25AnSpTslWht, GBCyl25DrpGl, GBCyl25DrpSl, GBCyl25RdcrIvyLthr, GBCyl25RdcrShnGl, GBcyl25AnSpIvyGl, GBcyl25AnSpIvySl, +18 more | F20: LBCyl25LtnCu | G20: 83 | H20: 105–109 | I20: 32 | J20: 45 | R20: =IF(COUNTA(K20:Q20)=0,"To answer",IF(AND(K20="",Q20=""),"Add the right height","Answered"))

Sheet All bottles
A1: Bottle # | B1: Priority | C1: Bottle | D1: Governing SKU | E1: Product | F1: SKUs on this bottle | G1: Height without cap now (mm) | H1: Height with cap now, min (mm) | I1: Height with cap now, max (mm) | J1: Diameter now (mm) | K1: Is the height without cap right? | L1: Right height without cap (mm) | M1: Right height with cap (mm) | N1: Right diameter (mm) | O1: How you checked | P1: Comment | Q1: Review status
A2: 8 | B2: Issue | C2: Apothecary · 118 ml · Ground · Standard · Pear | D2: GBPearClear4ozStpr | E2: Apothecary style 4oz Clear Pear Bottle with glass stopper. 118ml (3.99oz). Semi-automatic handmade bottle with proper fitting stopper. Not leak proof. For perfumes and fragrance oils. | F2: 1 | G2: 52.2 | H2: 77.3 | I2: 77.3 | J2: 27.4 | K2: See Issues to fix tab | Q2: On the Issues tab
A3: 14 | B3: Issue | C3: Boston Round · 30 ml · 20-400 · Standard | D3: GBBstn1ozBlkDrp | E3: Boston round design 30ml, 1oz Clear glass bottle with black dropper. For use with perfume oils, diffuser oils, serums, primers, facial oils or face oils, moisturizers, and beard oils. Price each | F3: 53 | G3: 78 | H3: 78 | I3: 102 | J3: 33 | K3: See Issues to fix tab | Q3: On the Issues tab
A4: 23 | B4: Issue | C4: Cream Jar · 3 ml · 20mm · Standard | D4: CJBlu3 | E4: Plastic, cream jar style 3 ml bottle with blue cap. For use with body butters, creams, and thick lotions. Small trial or sample size. Great for promotions. Price each | F4: 2 | G4: 18 | H4: 24 | I4: 50 | J4: 35 | K4: See Issues to fix tab | Q4: On the Issues tab
A5: 24 | B5: Issue | C5: Cream Jar · 5 ml · 27mm · Standard | D5: CJAmb5mlBlkCap | E5: Cream glass jar style 5 ml amber bottle with black cap. For use with body butters, creams, and thick lotions. Small trial or sample size. Great for promotions. Price each | F5: 2 | G5: 24 | H5: 18 | I5: 28 | J5: 31 | K5: See Issues to fix tab | Q5: On the Issues tab
A6: 26 | B6: Issue | C6: Cream Jar · 15 ml · 37mm · Standard | D6: CJClr15Pnk | E6: Plastic, cream jar style 15 ml bottle with pink cap. For use with body butters, creams, and thick lotions. Small trial or sample size. Great for promotions. Price each | F6: 2 | G6: 26 | H6: 29 | I6: 31 | J6: 55 | K6: See Issues to fix tab | Q6: On the Issues tab
A7: 34 | B7: Issue | C7: Cylinder · 5 ml · 13-415 · Standard | D7: GBCyl5BlkSht | E7: 5 mL Clear Cylinder Bottle with Short Ribbed Black Cap | F7: 70 | G7: 53 | H7: 55 | I7: 80 | J7: 17 | K7: See Issues to fix tab | Q7: On the Issues tab
A8: 41 | B8: Issue | C8: Cylinder · 25 ml · 18-415 · Standard | D8: LBCyl25LtnCu | E8: Cylinder design 25ml clear glass bottle with matte copper lotion pump. For use with cologne, Eau de Parfum, air freshner, face and body spray, or room spray. Cylinder design is a family of bottles available in 25ml, 50ml and 100ml sizes. | F8: 45 | G8: 83 | H8: 105 | I8: 109 | J8: 32 | K8: See Issues to fix tab | Q8: On the Issues tab
A9: 43 | B9: Issue | C9: Cylinder · 30 ml · 18-415 · Standard | D9: GBSpry1ozGl | E9: Clear Glass Spray Bottle with Gold Top and Base. Capacity: 1oz (30ml) | F9: 2 | G9: 50.8 | H9: 70.7 | I9: 70.7 | J9: 42 | K9: See Issues to fix tab | Q9: On the Issues tab
A10: 56 | B10: Issue | C10: Decorative · 35 ml · Ground · Standard · Eternal Flame | D10: GBEternalFlameClear | E10: Clear glass bottle with ground glass neck and stopper.Capacity: Approx 1 1/4oz (35ml) | F10: 3 | G10: 44 | H10: 80 | I10: 82 | J10: 63 | K10: See Issues to fix tab | Q10: On the Issues tab
A11: 60 | B11: Issue | C11: Diva · 46 ml · 18-415 · Frosted | D11: GBDiva46DrpSl | E11: Diva design 46 ml bottle with white dropper with shiny silver collar cap, price each | F11: 44 | G11: 89 | H11: 93 | I11: 116 | J11: 49 | K11: See Issues to fix tab | Q11: On the Issues tab
A12: 63 | B12: Issue | C12: Elegant · 15 ml · 13-415 · Frosted | D12: GBElgFrst15BlkShSht | E12: Elegant design 15ml, 1/2oz frosted glass bottle with short shiny black cap. | F12: 36 | G12: 61 | H12: 66 | I12: 95 | J12: 35 | K12: See Issues to fix tab | Q12: On the Issues tab
A13: 67 | B13: Issue | C13: Elegant · 60 ml · 18-415 · Frosted | D13: GBElgFrst60AnSpBlk | E13: Elegant design 60 ml, 2oz frosted glass bottle with black vintage style bulb sprayer with shiny silver collar cap. For use with cologne, Eau de Parfum, air freshner, face and body spray, or room spray. Antique or vintage bulb sprayers enhance the beauty | F13: 47 | G13: 86 | H13: 90 | I13: 135 | J13: 54 | K13: See Issues to fix tab | Q13: On the Issues tab
... A20: 106 | B20: Issue | C20: Vial · 3 ml · 13-425 · Standard | D20: GBVGreen2o4BlackCapSht | E20: Vial design 5/8 dram Green glass vial with black short cap. For use with perfume or fragrance oil, essential oil, aromatherapy, sample or trial size. Perfume sample vials for promotions. Price each | F20: 3 | G20: 29 | H20: 20 | I20: 75 | J20: 14 | K20: See Issues to fix tab | Q20: On the Issues tab
A21: 15 | B21: High volume | C21: Boston Round · 60 ml · 20-400 · Standard | D21: GBBstn2ozBlkCapSht | E21: Boston round design 60ml, 2oz Clear glass bottle with short black cap. For use with Perfume oils, essential oils, diffuser oils and aromatherapy. Price each | F21: 55 | G21: 94 | H21: 110 | I21: 117 | J21: 39 | Q21: =IF(K21="","To check",IF(K21="Correct","Confirmed",IF(K21="Not sure","Not sure",IF(L21="","Add the right height","Correction given"))))
A22: 16 | B22: High volume | C22: Circle · 15 ml · 13-415 · Standard | D22: GBCrcl15BlkSht | E22: Circle design 15ml, 1/2oz Clear glass bottle with short black cap. For use with perfume or fragrance oil, essential oils, aromatic oils and aromatherapy. Refillable, classic style bottle good for promotions and decants. Price each | F22: 36 | G22: 60 | H22: 62 | I22: 80 | J22: 50 | Q22: =IF(K22="","To check",IF(K22="Correct","Confirmed",IF(K22="Not sure","Not sure",IF(L22="","Add the right height","Correction given"))))
A23: 19 | B23: High volume | C23: Circle · 50 ml · 18-415 · Frosted | D23: GBCrclFrst50AnSpBlk | E23: Circle design 50 ml, 1.7oz frosted glass bottle with black vintage style bulb sprayer with shiny silver collar cap. For use with cologne, Eau de Parfum, air freshner, face and body spray, or room spray. Antique or vintage bulb sprayers enhance the beau | F23: 44 | G23: 87 | H23: 91 | I23: 115 | J23: 72 | Q23: =IF(K23="","To check",IF(K23="Correct","Confirmed",IF(K23="Not sure","Not sure",IF(L23="","Add the right height","Correction given"))))
A24: 20 | B24: High volume | C24: Circle · 50 ml · 18-415 · Standard | D24: GBCrcl50AnSpBlk | E24: Circle design 50 ml, 1.7oz clear glass bottle with black vintage style bulb sprayer with shiny silver collar cap. For use with cologne, Eau de Parfum, air freshner, face and body spray, or room spray. Antique or vintage bulb sprayers enhance the beauty | F24: 46 | G24: 87 | H24: 91 | I24: 115 | J24: 72 | Q24: =IF(K24="","To check",IF(K24="Correct","Confirmed",IF(K24="Not sure","Not sure",IF(L24="","Add the right height","Correction given"))))
A25: 21 | B25: High volume | C25: Circle · 100 ml · 18-415 · Frosted | D25: GBCrclFrst100AnSpBlk | E25: Circle design 100 ml, 3 1/2oz frosted glass bottle with black vintage style bulb sprayer with shiny silver collar cap. For use with cologne, Eau de Parfum, air freshner, face and body spray, or room spray. Antique or vintage bulb sprayers enhance the bea | F25: 43 | G25: 105 | H25: 109 | I25: 136 | J25: 89 | Q25: =IF(K25="","To check",IF(K25="Correct","Confirmed",IF(K25="Not sure","Not sure",IF(L25="","Add the right height","Correction given"))))
A26: 22 | B26: High volume | C26: Circle · 100 ml · 18-415 · Standard | D26: GBCrcl100AnSpBlk | E26: Circle design 100 ml, 3 1/2oz clear glass bottle with black vintage style bulb sprayer with shiny silver collar cap. For use with cologne, Eau de Parfum, air freshner, face and body spray, or room spray. Antique or vintage bulb sprayers enhance the bea | F26: 43 | G26: 105 | H26: 109 | I26: 136 | J26: 89 | Q26: =IF(K26="","To check",IF(K26="Correct","Confirmed",IF(K26="Not sure","Not sure",IF(L26="","Add the right height","Correction given"))))
A27: 36 | B27: High volume | C27: Cylinder · 9 ml · 13-415 · Frosted · Tall | D27: GBTallCylFrst9BlkSht | E27: Tall cylinder design 9ml, 1/3oz frosted glass bottle with short black cap. For use with perfume or fragrance oil, essential oils, aromatic oils and aromatherapy. Refillable, slender bottle with attractive heavy base. Price each | F27: 36 | G27: 106 | H27: 109 | I27: 126 | J27: 18 | Q27: =IF(K27="","To check",IF(K27="Correct","Confirmed",IF(K27="Not sure","Not sure",IF(L27="","Add the right height","Correction given"))))
A28: 37 | B28: High volume | C28: Cylinder · 9 ml · 13-415 · Standard · Tall | D28: GBTallCyl9BlkSht | E28: Tall cylinder design 9ml, 1/3oz Clear glass bottle with short black cap. For use with perfume or fragrance oil, essential oils, aromatic oils and aromatherapy. Refillable, slender bottle with attractive heavy base. Price each | F28: 36 | G28: 106 | H28: 109 | I28: 126 | J28: 18 | Q28: =IF(K28="","To check",IF(K28="Correct","Confirmed",IF(K28="Not sure","Not sure",IF(L28="","Add the right height","Correction given"))))
A29: 39 | B29: High volume | C29: Cylinder · 9 ml · 17-415 · Standard | D29: GBCyl9MtlRollBlkDot | E29: Cylinder design 9ml,1/3 oz clear glass bottle with metal roller ball plug and black dot cap. For use with perfume or fragrance oil, essential oils, aromatic oils and aromatherapy. Price each | F29: 87 | G29: 70 | H29: 83 | I29: 98 | J29: 20 | Q29: =IF(K29="","To check",IF(K29="Correct","Confirmed",IF(K29="Not sure","Not sure",IF(L29="","Add the right height","Correction given"))))
A30: 45 | B30: High volume | C30: Cylinder · 50 ml · 18-415 · Standard | D30: GBCyl50AnSpBlk | E30: Cylinder design 50 ml, 1.7oz clear glass bottle with black vintage style bulb sprayer with shiny silver collar cap. For use with cologne, Eau de Parfum, air freshner, face and body spray, or room spray. Antique or vintage bulb sprayers enhance the beau | F30: 43 | G30: 117 | H30: 121 | I30: 142 | J30: 32 | Q30: =IF(K30="","To check",IF(K30="Correct","Confirmed",IF(K30="Not sure","Not sure",IF(L30="","Add the right height","Correction given"))))
A31: 46 | B31: High volume | C31: Cylinder · 100 ml · 18-415 · Standard | D31: GBCyl100AnSpBlk | E31: Cylinder design 100 ml, 3 1/2oz clear glass bottle with black vintage style bulb sprayer with shiny silver collar cap. For use with cologne, Eau de Parfum, air freshner, face and body spray, or room spray. Antique or vintage bulb sprayers enhance the b | F31: 43 | G31: 154 | H31: 173 | I31: 199 | J31: 35 | Q31: =IF(K31="","To check",IF(K31="Correct","Confirmed",IF(K31="Not sure","Not sure",IF(L31="","Add the right height","Correction given"))))
A32: 58 | B32: High volume | C32: Diamond · 60 ml · 18-415 · Standard | D32: GBDmnd2ozAnSpBlk | E32: Diamond design 60ml, 2 ounce clear glass bottle with black vintage style bulb sprayer with shiny silver collar cap. For use with cologne, Eau de Parfum, air freshner, face and body spray, or room spray. Antique or vintage bulb sprayers enhance the beau | F32: 43 | G32: 88 | H32: 92 | I32: 115 | J32: 39 | Q32: =IF(K32="","To check",IF(K32="Correct","Confirmed",IF(K32="Not sure","Not sure",IF(L32="","Add the right height","Correction given"))))
... A109: 108 | B109: Spot check | C109: Vial · 9 ml · 18-400 · Standard | D109: GB09BlackCapApp | E109: Cylinder design 9 ml clear glass vial with black cap with glass rod applicator. For use with perfume or fragrance oil, essential oil, aromatherapy. Small sample or trial size vial. Price each | F109: 2 | G109: 79.4 | H109: 47 | I109: 50 | J109: 20 | Q109: =IF(K109="","To check",IF(K109="Correct","Confirmed",IF(K109="Not sure","Not sure",IF(L109="","Add the right height","Correction given"))))

Sheet SKU detail
A1: Bottle # | B1: Website SKU | C1: Product | D1: Glass colour | E1: Applicator | F1: Cap colour | G1: Height without cap (mm) | H1: Height with cap (mm) | I1: Diameter (mm) | J1: As recorded
A2: 1 | B2: Alu65mlLotionPumpBlack | C2: Cylinder shaped, brushed aluminum 65 ml bottle with lotion black. For use with lotion or treatment pump. Price Each | F2: Black | G2: 94 | H2: 130 | I2: 36 | J2: 94 ±1 mm
A3: 1 | B3: Alu65mlLotionPumpWhite | C3: Cylinder shaped, brushed aluminum 65 ml bottle with lotion white. For use with lotion or treatment pump. Price Each | F3: White | G3: 94 | H3: 127 | I3: 36 | J3: 94 ±1 mm
A4: 2 | B4: Alu100mlSprayBlack | C4: Cylinder shaped, matte aluminum 100 ml bottle with black sprayer. For use with cologne, perfume, air freshner, face and body spray, or room spray. Price Each | F4: Black | G4: 127.8 | H4: 150 | I4: 50 | J4: 127.8
A5: 3 | B5: Alu120mlLotionPumpBlack | C5: Cylinder shaped, brushed aluminum 120 ml bottle with lotion black. For use with lotion or treatment pump. Price Each | F5: Black | G5: 114 | H5: 147 | I5: 45 | J5: 114 ±2 mm
A6: 3 | B6: Alu120mlLotionPumpWhite | C6: Cylinder shaped, brushed aluminum 120 ml bottle with lotion white. For use with lotion or treatment pump. Price Each | F6: White | G6: 114 | H6: 147 | I6: 45 | J6: 114 ±2 mm
A7: 4 | B7: Alu250mlSprayBlack | C7: Aluminum Bottle 250 ml (8.45 oz) Clear Aluminum Bottle with Sprayer Black Cap | D7: Clear | E7: Fine Mist Sprayer | F7: Black | G7: 127.8 | H7: 180 | I7: 60 | J7: 127.8
A8: 5 | B8: Alu500 | C8: Cylinder shaped, aluminum 500 ml bottle with white plug and tear off cap. For use with perfume oil, aromatic oils, fragrance oils and attars. Price Each | F8: Clear | G8: 178 | H8: 186 | I8: 74 | J8: 178 ±2 mm
A9: 6 | B9: GB15ApthBlue | C9: Apothecary style 15 ml blue glass bottle with blue glass stopper. For use with perfume or fragrance oil, essential oil, aromatherapy. Good for displaying products. These are hand made bottles with ground glass stoppers. The stoppers are not leak proof, | D9: Cobalt Blue | E9: Glass Stopper | F9: Blue | G9: 58 | H9: 82 | I9: 30 | J9: 58 ±1 mm
A10: 7 | B10: GB1ozApth | C10: Apothecary style 30ml clear glass bottle with glass stopper. For use with perfume or fragrance oil, essential oil, aromatherapy. Good for displaying products. These are hand made bottles with ground glass stoppers. The stoppers are not leak proof, and wil | D10: Clear | E10: Glass Stopper | F10: Clear | G10: 58 | H10: 98 | I10: 37 | J10: 58
A11: 7 | B11: GB1ozApthBlue | C11: Apothecary style 30ml blue glass bottle with blue glass stopper. For use with perfume or fragrance oil, essential oil, aromatherapy. Good for displaying products. These are hand made bottles with ground glass stoppers. The stoppers are not leak proof, and | D11: Cobalt Blue | E11: Glass Stopper | F11: Blue | G11: 58 | H11: 98 | I11: 37 | J11: 58
A12: 7 | B12: GB1ozApthGreen | C12: Apothecary style 30ml green glass bottle with green glass stopper. For use with perfume or fragrance oil, essential oil, aromatherapy. Good for displaying products. These are hand made bottles with ground glass stoppers. The stoppers are not leak proof, a | D12: Green | E12: Glass Stopper | F12: Green | G12: 58 | H12: 98 | I12: 37 | J12: 58
A13: 8 | B13: GBPearClear4ozStpr | C13: Apothecary style 4oz Clear Pear Bottle with glass stopper. 118ml (3.99oz). Semi-automatic handmade bottle with proper fitting stopper. Not leak proof. For perfumes and fragrance oils. | D13: Clear | F13: Clear | G13: 52.2 | H13: 77.3 | I13: 27.4 | J13: 52.2
A14: 9 | B14: GBAtom5SlimBlk | C14: Black slim atomizer design 5 ml bottle. For use with perfumes, Colognes, eau de Parfum. Refillable, travel size atomizer. Can be laser engraved and customized. Great for gifts and promotion. Price each | D14: Black | E14: Atomizer | F14: Black | G14: 92 | H14: 104 | I14: 15 | J14: 92 ±1 mm
A15: 9 | B15: GBAtom5SlimGl | C15: Gold slim atomizer design 5 ml bottle. For use with perfumes, Colognes, eau de Parfum. Refillable, travel size atomizer. Can be laser engraved and customized. Great for gifts and promotion. Price each | D15: Clear | E15: Atomizer | F15: Gold | G15: 92 | H15: 104 | I15: 15 | J15: 92 ±1 mm
A16: 9 | B16: GBAtom5SlimSl | C16: Silver slim atomizer design 5 ml bottle. For use with perfumes, Colognes, eau de Parfum. Refillable, travel size atomizer. Can be laser engraved and customized. Great for gifts and promotion. Price each | D16: Clear | E16: Atomizer | F16: Silver | G16: 92 | H16: 104 | I16: 15 | J16: 92 ±1 mm
A17: 10 | B17: GBAtom5Blk | C17: Black atomizer design 5 ml bottle. For use with perfumes, Colognes, eau de Parfum. Refillable, travel size atomizer. Can be laser engraved and customized. Great for gifts and promotion. Price each | D17: Black | E17: Atomizer | F17: Black | G17: 76 | H17: 81 | I17: 18 | J17: 76 ±1 mm
A18: 10 | B18: GBAtom5BlkDot | C18: Black atomizer design 5 ml bottle with dots. | D18: Black | E18: Atomizer | F18: Black | G18: 76 | H18: 81 | I18: 18 | J18: 76 ±1 mm
A19: 10 | B19: GBAtom5Blu | C19: Blue atomizer design 5 ml bottle. For use with perfumes, Colognes, eau de Parfum. Refillable, travel size atomizer. Can be laser engraved and customized. Great for gifts and promotion. Price each | D19: Cobalt Blue | E19: Atomizer | F19: Blue | G19: 76 | H19: 81 | I19: 18 | J19: 76 ±1 mm
A20: 10 | B20: GBAtom5Gl | C20: Gold atomizer design 5 ml bottle. For use with perfumes, Colognes, eau de Parfum. Refillable, travel size atomizer. Can be laser engraved and customized. Great for gifts and promotion. Price each | D20: Clear | E20: Atomizer | F20: Gold | G20: 76 | H20: 81 | I20: 18 | J20: 76 ±1 mm
A21: 10 | B21: GBAtom5PnkDot | C21: Pink atomizer design 5 ml bottle with dots. | D21: Pink | E21: Atomizer | F21: Pink | G21: 76 | H21: 81 | I21: 18 | J21: 76 ±1 mm
A22: 10 | B22: GBAtom5Red | C22: Red atomizer design 5 ml bottle. For use with perfumes, Colognes, eau de Parfum. Refillable, travel size atomizer. Can be laser engraved and customized. Great for gifts and promotion. Price each | D22: Clear | E22: Atomizer | F22: Red | G22: 76 | H22: 81 | I22: 18 | J22: 76 ±1 mm
A23: 10 | B23: GBAtom5Sl | C23: Silver atomizer design 5 ml bottle. For use with perfumes, Colognes, eau de Parfum. Refillable, travel size atomizer. Can be laser engraved and customized. Great for gifts and promotion. Price each | D23: Clear | E23: Atomizer | F23: Silver | G23: 76 | H23: 81 | I23: 18 | J23: 76 ±1 mm
A24: 10 | B24: GBAtom5SlDot | C24: Silver atomizer and sprayer with dots, design 5 ml bottle with dots. For use with perfumes, Colognes, eau de Parfum. Refillable, travel size atomizer. Can be laser engraved and customized. Great for gifts and promotion. Price each | D24: Clear | E24: Atomizer | F24: Silver | G24: 76 | H24: 104 | I24: 18 | J24: 76 ±1 mm
A25: 10 | B25: GBAtom5SlStars | C25: Silver atomizer design 5 ml bottle with star patterns. For use with perfumes, Colognes, eau de Parfum. Refillable, travel size atomizer. Can be laser engraved and customized. Great for gifts and promotion. Price each | D25: Clear | E25: Atomizer | F25: Silver | G25: 76 | H25: 81 | I25: 18 | J25: 76 ±1 mm
... A40: 12 | B40: GBBell10SpryBlkSh | C40: Bell design 10ml Clear glass bottle with shiny black spray. Fine mist sprayer for use with perfumes and colognes. Refillable, classic style bottle good for promotions and decants. Price each | D40: Clear | E40: Fine Mist Sprayer | F40: Shiny Black | G40: 55 | H40: 20 | I40: 27 | J40: 55 ±1 mm
A41: 13 | B41: GBBstn15BlkCapSht | C41: Boston round design 15ml, 1/2 oz Clear glass bottle with short black cap. For use with Perfume oils, essential oils, diffuser oils and aromatherapy. Price each | D41: Clear | F41: Black | G41: 68 | H41: 72 | I41: 25 | J41: 68 ±1 mm
A42: 13 | B42: GBBstn15BlkDrp | C42: Boston round design 15ml, 1/2 oz Clear glass bottle with a black dropper. For use with perfume oils, diffuser oils, ser | D42: Clear | E42: N/A | G42: 68 | H42: 91 | I42: 25 | J42: 68 ±1 mm Item Diameter: 25 ±0.
A43: 13 | B43: GBBstnAmb15mlBlkCapSht | C43: Boston round design 15ml, 1/2 oz Amber glass bottle with short black cap. For use with Perfume oils, essential oils, diffuser oils and aromatherapy. Price each | D43: Amber | F43: Black | G43: 68 | H43: 72 | I43: 25 | J43: 68 ±1 mm
A44: 13 | B44: GBBstnAmb15mlBlkDropper | C44: Boston round design 15ml, 1/2 oz Amber glass bottle with a black dropper. For use with perfume oils, diffuser oils, serums, primers, facial oils or face oils, moisturizers, and beard oils. Price each | D44: Amber | E44: Dropper | F44: Black | G44: 68 | H44: 91 | I44: 25 | J44: 68 ±1 mm
A45: 13 | B45: GBBstnAmb15mlBlkDropperGlTrim | C45: Boston round design 15ml, 1/2 oz Amber glass bottle with black dropper with a shiny gold trim cap. For use with perfume oils, diffuser oils, serums, primers, facial oils or face oils, moisturizers, and beard oils. Price each | D45: Amber | E45: Dropper | F45: Black | G45: 68 | H45: 91 | I45: 25 | J45: 68 ±1 mm
A46: 13 | B46: GBBstnAmb15mlBlkDropperSlTrim | C46: Boston round design 15ml, 1/2 oz Amber glass bottle and black dropper with a shiny silver trim cap. For use with perfume oils, diffuser oils, serums, primers, facial oils or face oils, moisturizers, and beard oils. Price each | D46: Amber | E46: Dropper | F46: Black | G46: 68 | H46: 91 | I46: 25 | J46: 68 ±1 mm
A47: 13 | B47: GBBstnAmb15mlWhtDropper | C47: Boston round design 15ml, 1/2 oz Amber glass bottle with a white dropper. For use with perfume oils, diffuser oils, serums, primers, facial oils or face oils, moisturizers, and beard oils. Price each | D47: Amber | E47: Dropper | F47: White | G47: 68 | H47: 91 | I47: 25 | J47: 68 ±1 mm
A48: 13 | B48: GBBstnAmb15mlWhtDropperGlTrim | C48: Boston round design 15ml, 1/2 oz Amber glass bottle and white dropper with a shiny gold trim cap. For use with perfume oils, diffuser oils, serums, primers, facial oils or face oils, moisturizers, and beard oils. Price each | D48: Amber | E48: Dropper | F48: White | G48: 68 | H48: 91 | I48: 25 | J48: 68 ±1 mm
A49: 13 | B49: GBBstnAmb15mlWhtDropperSlTrim | C49: Boston round design 15ml, 1/2 oz Amber glass bottle and white dropper with a shiny silver trim cap. For use with perfume oils, diffuser oils, serums, primers, facial oils or face oils, moisturizers, and beard oils. Price each | D49: Amber | E49: Dropper | F49: White | G49: 68 | H49: 91 | I49: 25 | J49: 68 ±1 mm
A50: 13 | B50: GBBstnBlu15BlkCapSht | C50: Boston round design 15ml, 1/2 oz Cobalt blue glass bottle with short black cap. For use with Perfume oils, essential oils, diffuser oils and aromatherapy. Price each | D50: Cobalt Blue | F50: Black | G50: 68 | H50: 72 | I50: 25 | J50: 68 ±1 mm
A51: 13 | B51: GBBstnBlu15BlkDrpr | C51: Boston round design 15ml, 1/2 oz Cobalt blue glass bottle with a black dropper. For use with perfume oils, diffuser oils, serums, primers, facial oils or face oils, moisturizers, and beard oils. Price each | D51: Cobalt Blue | E51: Dropper | F51: Black | G51: 68 | H51: 91 | I51: 25 | J51: 68 ±1 mm
A52: 13 | B52: GBBstnBlu15BlkDrprGlTrim | C52: Boston round design 15ml, 1/2 oz Cobalt blue glass bottle with black dropper shiny gold trim cap. For use with perfume oils, diffuser oils, serums, primers, facial oils or face oils, moisturizers, and beard oils. Price each | D52: Cobalt Blue | E52: Dropper | F52: Black | G52: 68 | H52: 91 | I52: 25 | J52: 68 ±1 mm
A53: 13 | B53: GBBstnBlu15WhtDrpr | C53: Boston round design 15ml, 1/2 oz Cobalt blue glass bottle with a white dropper. For use with perfume oils, diffuser oils, serums, primers, facial oils or face oils, moisturizers, and beard oils. Price each | D53: Cobalt Blue | E53: Dropper | F53: White | G53: 68 | H53: 91 | I53: 25 | J53: 68 ±1 mm
A54: 13 | B54: GBBstnBlu15WhtDrprGlTrim | C54: Boston round design 15ml, 1/2 oz Cobalt blue glass bottle and white dropper and a shiny gold trim cap. For use with perfume oils, diffuser oils, serums, primers, facial oils or face oils, moisturizers, and beard oils. Price each | D54: Cobalt Blue | E54: Dropper | F54: White | G54: 68 | H54: 91 | I54: 25 | J54: 68 ±1 mm
...
